Workbook

Sheet CT unable to download
A1: clot burden score | B1: (Multiple Items)
A3: Name TRISHA EXCEL | B3: V4
A4: Hira salve | B4: 230802743
A5: Mandhar Zurekar | B5: 230010455
A6: Nursing shinde | B6: 230802341
A7: Pravin Dhumal Babanrao | B7: 220701846

Sheet MRI unable to download
A1: Stroke volume | B1: unable to download
A3: Name TRISHA EXCEL | B3: V4
A4: Ashok choudhari | B4: 211003182
A5: Belvalkar Madhav | B5: 240000032930
A6: Kaushalya Mane | B6: 240001711
A7: Putage Siddhavva Maruti | B7: 11111111111111
A8: Ramchandra Dhumal | B8: 230103376
A9: ratnamala gaikwad | B9: 240015649
A10: Ruben Gaikwad | B10: 230000052678
A11: Shinde Shivram | B11: 230003999
A12: Sushma deshpande | B12: 230502566
A13: #N/A | B13: 230000058666
B14: 240000031207
B15: 240000032777
B16: 240000050289

Sheet Dr Dulari Data Entry_21_feb_202
A1: Name | B1: age | C1: gender | D1: NIHSS | E1: SHT | F1: DM | G1: Alcohol | H1: tobacco | I1: smoking | J1: dyslipidaemia | K1: atrial fibrillation | L1: IHD | M1: rheumatic heart disease | N1: past history of stroke/TIA | O1: haemoglobin | P1: PCV | Q1: MCV | R1: Homocystiene | S1: HbA1C | T1: Cholesterol | U1: LDL Cholesterol | V1: HDL Cholesterol | W1: Triglycerides | X1: V LDL | Y1: b 12 | Z1: Vit D | AA1: CT ASPECTS | AB1: TAN | AC1: MAS | AD1: MITEFF | AE1: MCTA | AF1: Cerebral collaterals | AG1: ecosprine | AH1: clopidogril | AI1: thrombolysis | AJ1: thrombolytic agent | AK1: anticoagulation | AL1: mechanical thrombectomy | AM1: decompressive hemicranectomy | AN1: barthel index | AO1: Rt infraclinoid ICA | AP1: Rt Supraclinoid ICA | AQ1: Rt Proximal M1 MCA | AR1: Rt Distal M1 MCA | AS1: Rt M2MCA rear | AT1: Rt M2 MCA forward | AU1: Rt A1 ACA | AV1: Lt infraclinoid ICA | AW1: Lt Supraclinoid ICA | AX1: Lt Proximal M1 MCA | AY1: Lt Distal M1 MCA | AZ1: Lt M2MCA rear | BA1: Lt M2 MCA forward | BB1: Lt A1 ACA | BC1: clot burden score | BD1: Lt ICA origin | BE1: Rt ICA origin | BF1: CCA | BG1: MRS
A2: Prakash Deshmukh | B2: 72 | C2: 1 | D2: 22 | E2: 1 | F2: 1 | G2: 2 | H2: 2 | I2: 2 | J2: 2 | K2: 2 | L2: 2 | M2: 2 | N2: 2 | O2: 14.5 | P2: 43.1 | Q2: 87.6 | R2: 19.56 | S2: 5.9 | Y2: 186 | AA2: 9 | AB2: 1 | AC2: 2 | AD2: 1 | AE2: 4 | AF2: 0 | AG2: 1 | AH2: 2 | AI2: 1 | AJ2: 2 | AL2: 1 | AM2: 2 | AN2: 85 | AO2: 0 | AP2: 0 | AQ2: 0 | AR2: 0 | AS2: 0 | AT2: 0 | AU2: 0 | AV2: 0 | AW2: 0 | AX2: 0 | AY2: 0 | AZ2: 1 | BA2: 1 | BB2: 1 | BC2: 3 | BD2: 0 | BE2: 1 | BF2: 0 | BG2: 1
A3: Nilesh Dhande | B3: 46 | C3: 1 | D3: 3 | E3: 1 | F3: 2 | G3: 2 | H3: 2 | I3: 2 | J3: 2 | K3: 2 | L3: 2 | M3: 2 | N3: 2 | O3: 14.2 | P3: 43.9 | Q3: 82.6 | R3: 9 | S3: 5.5 | T3: 161 | U3: 88 | V3: 46 | W3: 132 | X3: 26 | AA3: 6 | AB3: 1 | AC3: 2 | AD3: 2 | AE3: 2 | AF3: 0 | AG3: 1 | AH3: 1 | AI3: 2 | AK3: 3 | AL3: 2 | AM3: 2 | AN3: 100 | AO3: 0 | AP3: 0 | AQ3: 0 | AR3: 0 | AS3: 0 | AT3: 0 | AU3: 0 | AV3: 0 | AW3: 0 | AX3: 2 | AY3: 2 | AZ3: 1 | BA3: 1 | BB3: 1 | BC3: 7 | BD3: 1 | BE3: 1 | BF3: 0 | BG3: 0
A4: Madhukar Khangute | B4: 82 | C4: 1 | D4: 22 | E4: 1 | F4: 1 | G4: 2 | H4: 2 | I4: 2 | J4: 2 | K4: 2 | L4: 1 | M4: 2 | N4: 2 | O4: 15.6 | P4: 45.9 | Q4: 89.4 | R4: 9.93 | S4: 8.2 | Y4: 1335 | AA4: 9 | AB4: 1 | AC4: 2 | AD4: 1 | AE4: 1 | AF4: 0 | AG4: 1 | AH4: 2 | AI4: 1 | AJ4: 2 | AL4: 2 | AM4: 2 | AN4: 0 | AO4: 0 | AP4: 0 | AQ4: 0 | AR4: 0 | AS4: 0 | AT4: 0 | AU4: 0 | AV4: 1 | AW4: 2 | AX4: 0 | AY4: 0 | AZ4: 0 | BA4: 0 | BB4: 0 | BC4: 3 | BD4: 1 | BE4: 1 | BF4: 0 | BG4: 6
A5: Bhalchandra govande | B5: 83 | C5: 1 | E5: 1 | F5: 1 | G5: 2 | H5: 2 | I5: 2 | J5: 2 | K5: 1 | L5: 2 | M5: 2 | N5: 1 | O5: 11.8 | P5: 42 | S5: 9.1 | T5: 120 | U5: 62 | V5: 25 | W5: 165 | X5: 33 | AA5: 7 | AB5: 1 | AC5: 2 | AD5: 1 | AE5: 1 | AF5: 0 | AG5: 1 | AH5: 2 | AI5: 2 | AK5: 4 | AL5: 2 | AM5: 2 | AN5: 0 | AO5: 0 | AP5: 2 | AQ5: 2 | AR5: 0 | AS5: 1 | AT5: 1 | AU5: 1 | AV5: 0 | AW5: 0 | AX5: 0 | AY5: 0 | AZ5: 0 | BA5: 0 | BB5: 0 | BC5: 7 | BD5: 1 | BE5: 1 | BF5: Rt CCA plaque | BG5: 6
A6: Dharmraj Patil | B6: 78 | C6: 1 | D6: 16 | E6: 1 | F6: 1 | G6: 2 | H6: 1 | I6: 2 | J6: 2 | K6: 2 | L6: 2 | M6: 2 | N6: 2 | O6: 13.1 | P6: 39.9 | Q6: 84.2 | R6: 8.3 | S6: 6.4 | T6: 157 | U6: 90.4 | V6: 43 | W6: 118 | X6: 23.6 | AA6: 8 | AB6: 2 | AC6: 1 | AD6: 2 | AE6: 5 | AF6: 0 | AG6: 1 | AH6: 2 | AI6: 1 | AJ6: 1 | AL6: 2 | AM6: 2 | AN6: 65 | AO6: 0 | AP6: 2 | AQ6: 2 | AR6: 2 | AS6: 1 | AT6: 1 | AU6: 1 | AV6: 0 | AW6: 0 | AX6: 0 | AY6: 0 | AZ6: 0 | BA6: 0 | BB6: 0 | BC6: 9 | BD6: 0 | BE6: 0 | BF6: 0 | BG6: 2
A7: Kiran Pardeshi | B7: 71 | C7: 1 | D7: 3 | E7: 2 | F7: 2 | G7: 1 | H7: 1 | I7: 2 | J7: 2 | K7: 2 | L7: 2 | M7: 2 | N7: 2 | O7: 18 | P7: 53.8 | Q7: 10.59 | R7: 29.81 | Y7: 148 | AA7: 8 | AB7: 2 | AC7: 1 | AD7: 2 | AE7: 4 | AF7: 0 | AG7: 1 | AH7: 1 | AI7: 2 | AL7: 2 | AM7: 2 | AN7: 100 | AV7: 0 | AW7: 1 | AX7: 2 | AY7: 2 | AZ7: 1 | BA7: 1 | BB7: 1 | BC7: 8 | BD7: 1 | BE7: 1 | BF7: Bilateral CCA plaque | BG7: 0
A8: Dharmendra Kale | B8: 47 | C8: 1 | D8: 0 | E8: 1 | F8: 2 | G8: 2 | H8: 2 | I8: 2 | J8: 2 | K8: 2 | L8: 2 | M8: 2 | N8: 2 | O8: 12.9 | P8: 39 | Q8: 80 | R8: 40 | S8: 5.8 | Y8: 177 | AA8: 10 | AB8: 2 | AC8: 1 | AD8: 3 | AE8: 4 | AF8: 0 | AG8: 1 | AH8: 1 | AI8: 2 | AL8: 2 | AM8: 2 | AN8: 100 | AO8: 0 | AP8: 0 | AQ8: 0 | AR8: 0 | AS8: 0 | AT8: 0 | AU8: 0 | AV8: 1 | AW8: 1 | AX8: 2 | AY8: 2 | AZ8: 1 | BA8: 1 | BB8: 1 | BC8: 9 | BD8: 1 | BE8: 1 | BF8: Left CCA plaque | BG8: 0
A9: Vilas Gaikwad | B9: 51 | C9: 1 | D9: 20 | E9: 1 | F9: 1 | G9: 1 | H9: 1 | I9: 1 | J9: 2 | K9: 2 | L9: 2 | M9: 2 | N9: 2 | O9: 8.5 | P9: 29.3 | Q9: 59.7 | R9: 4.36 | S9: 8.2 | T9: 90 | U9: 42.2 | V9: 21 | W9: 134 | X9: 26.3 | Y9: 795 | AA9: 3 | AB9: 2 | AC9: 2 | AD9: 2 | AE9: 3 | AF9: 0 | AG9: 1 | AI9: 2 | AJ9: 1 | AL9: 2 | AM9: 2 | AN9: 55 | AO9: 0 | AP9: 0 | AQ9: 0 | AR9: 0 | AS9: 0 | AT9: 0 | AU9: 0 | AV9: 1 | AW9: 2 | AX9: 2 | AY9: 2 | AZ9: 0 | BA9: 1 | BB9: 1 | BC9: 9 | BD9: 0 | BE9: 1 | BF9: 0 | BG9: 3
A10: Keshavbai shinde | B10: 50 | C10: 2 | D10: 3 | E10: 2 | F10: 2 | G10: 2 | H10: 1 | I10: 2 | J10: 2 | K10: 2 | L10: 2 | M10: 2 | N10: 2 | O10: 13.2 | P10: 40.3 | Q10: 76.5 | R10: 7.34 | S10: 5.8 | T10: 173 | U10: 102.8 | V10: 39 | W10: 156 | X10: 31.2 | Y10: 1099 | AA10: 10 | AB10: 2 | AC10: 2 | AD10: 1 | AE10: 4 | AF10: 0 | AG10: 2 | AH10: 2 | AI10: 2 | AL10: 2 | AM10: 2 | AN10: 100 | AO10: 0 | AP10: 0 | AQ10: 0 | AR10: 0 | AS10: 0 | AT10: 0 | AU10: 0 | AV10: 0 | AW10: 0 | AX10: 2 | AY10: 2 | AZ10: 1 | BA10: 1 | BB10: 1 | BC10: 7 | BD10: 0 | BE10: 1 | BF10: 0 | BG10: 0
A11: Hanumant Gaikwad | B11: 84 | C11: 1 | D11: 7 | E11: 1 | F11: 2 | G11: 2 | H11: 2 | I11: 2 | J11: 2 | K11: 2 | L11: 2 | M11: 2 | N11: 2 | O11: 13.1 | P11: 37.8 | Q11: 90 | S11: 5.5 | T11: 229 | U11: 162.6 | V11: 35 | W11: 157 | X11: 31.4 | Y11: 421 | AA11: 10 | AB11: 2 | AC11: 2 | AD11: 3 | AE11: 4 | AF11: 0 | AG11: 1 | AH11: 2 | AI11: 1 | AJ11: 1 | AL11: 2 | AM11: 2 | AN11: 0 | AO11: 0 | AP11: 2 | AQ11: 2 | AR11: 2 | AS11: 1 | AT11: 1 | AU11: 1 | AV11: 0 | AW11: 0 | AX11: 0 | AY11: 0 | AZ11: 0 | BA11: 0 | BB11: 0 | BC11: 9 | BD11: 0 | BE11: 1 | BF11: 0 | BG11: 6
A12: Akbar Bhagawan | B12: 43 | C12: 1 | D12: 12 | E12: 1 | F12: 1 | G12: 2 | H12: 2 | I12: 2 | J12: 2 | K12: 2 | L12: 1 | M12: 2 | N12: 2 | O12: 10.5 | P12: 32.7 | Q12: 79.4 | R12: 10.77 | T12: 190 | U12: 135 | V12: 25 | W12: 150 | X12: 30 | Y12: 259 | AA12: 9 | AB12: 2 | AC12: 1 | AD12: 3 | AE12: 4 | AF12: 0 | AG12: 1 | AH12: 1 | AI12: 2 | AK12: 4 | AL12: 2 | AM12: 2 | AN12: 0 | AV12: 0 | AW12: 1 | AX12: 2 | AY12: 2 | AZ12: 1 | BA12: 1 | BB12: 1 | BC12: 8 | BD12: 0 | BE12: 1 | BF12: 0 | BG12: 6
A13: Jaydep B Panchal | B13: 30 | C13: 1 | D13: 9 | E13: 2 | F13: 2 | G13: 1 | H13: 2 | I13: 1 | J13: 2 | K13: 2 | L13: 2 | M13: 2 | N13: 1 | AA13: 10 | AB13: 2 | AC13: 2 | AD13: 2 | AE13: 4 | AF13: 0 | AG13: 1 | AH13: 2 | AI13: 1 | AJ13: 1 | AN13: 95 | AO13: 1 | AP13: 2 | AQ13: 0 | AR13: 0 | AS13: 1 | AT13: 1 | AU13: 1 | AV13: 0 | AW13: 0 | AX13: 0 | AY13: 0 | AZ13: 0 | BA13: 0 | BB13: 0 | BC13: 6 | BD13: 1 | BE13: 1 | BF13: 0 | BG13: 0
A14: Ashok Gite | B14: 57 | C14: 1 | D14: 7 | E14: 1 | F14: 1 | G14: 2 | H14: 1 | I14: 2 | J14: 2 | K14: 2 | L14: 1 | M14: 2 | N14: 2 | O14: 14.3 | P14: 44.4 | Q14: 81.8 | R14: 20.17 | S14: 7 | T14: 141 | U14: 88.4 | V14: 29 | W14: 118 | X14: 23.6 | Y14: 208 | AA14: 7 | AB14: 2 | AC14: 1 | AD14: 2 | AE14: 5 | AF14: 0 | AG14: 1 | AH14: 1 | AI14: 2 | AL14: 2 | AM14: 2 | AN14: 100 | AO14: 0 | AP14: 1 | AQ14: 0 | AR14: 1 | AS14: 1 | AT14: 1 | AU14: 1 | AV14: 0 | AW14: 0 | AX14: 0 | AY14: 0 | AZ14: 0 | BA14: 0 | BB14: 0 | BC14: 5 | BD14: 1 | BE14: 0 | BF14: 0 | BG14: 0
A15: Rekha Bhapkar | B15: 67 | C15: 2 | D15: 23 | E15: 2 | F15: 2 | G15: 2 | H15: 2 | I15: 2 | J15: 2 | K15: 2 | L15: 2 | M15: 1 | N15: 2 | O15: 9.4 | P15: 29.3 | Q15: 95.9 | AA15: 8 | AB15: 2 | AC15: 2 | AD15: 3 | AE15: 4 | AF15: 0 | AG15: 1 | AH15: 1 | AI15: 2 | AL15: 2 | AM15: 2 | AO15: 0 | AP15: 0 | AQ15: 2 | AR15: 2 | AS15: 1 | AT15: 1 | AU15: 1 | AV15: 0 | AW15: 0 | AX15: 0 | AY15: 0 | AZ15: 0 | BA15: 0 | BB15: 0 | BC15: 7 | BD15: 1 | BE15: 0 | BF15: Right CCA plaque | BG15: 6
A16: Chandrabhagabai Gite | B16: 77 | C16: 2 | D16: 1 | E16: 1 | F16: 1 | G16: 2 | H16: 2 | I16: 2 | J16: 2 | K16: 2 | L16: 2 | M16: 2 | N16: 2 | O16: 14 | P16: 42.4 | Q16: 88.9 | R16: 15.99 | S16: 10.4 | T16: 250 | U16: 126 | V16: 37 | W16: 435 | X16: 87 | AA16: 8 | AB16: 2 | AC16: 1 | AD16: 4 | AE16: 5 | AF16: 0 | AG16: 1 | AH16: 1 | AI16: 2 | AL16: 2 | AM16: 2 | AN16: 100 | AO16: 0 | AP16: 2 | AQ16: 2 | AR16: 2 | AS16: 1 | AT16: 1 | AU16: 1 | AV16: 0 | AW16: 0 | AX16: 0 | AY16: 0 | AZ16: 0 | BA16: 0 | BB16: 0 | BC16: 9 | BD16: 1 | BE16: 0 | BF16: Rt CCA plaque | BG16: 0
A17: Indubai Sarang | B17: 80 | C17: 2 | D17: 17 | E17: 1 | F17: 1 | G17: 2 | H17: 2 | I17: 2 | J17: 2 | K17: 2 | L17: 2 | M17: 2 | N17: 2 | O17: 12.9 | P17: 38.5 | Q17: 92 | R17: 31.04 | S17: 11.4 | T17: 130 | U17: 68.8 | V17: 31 | W17: 151 | X17: 30.2 | Y17: 198 | AA17: 9 | AB17: 2 | AC17: 2 | AD17: 3 | AE17: 4 | AF17: 0 | AG17: 1 | AH17: 1 | AI17: 2 | AL17: 2 | AM17: 2 | AN17: 100 | AO17: 0 | AP17: 0 | AQ17: 0 | AR17: 0 | AS17: 0 | AT17: 0 | AU17: 0 | AV17: 0 | AW17: 2 | AX17: 1 | AY17: 2 | AZ17: 1 | BA17: 1 | BB17: 1 | BC17: 8 | BD17: 1 | BE17: 0 | BF17: 0 | BG17: 5
A18: Malusare suresh | B18: 70 | C18: 1 | E18: 2 | F18: 1 | G18: 2 | H18: 1 | I18: 2 | J18: 2 | K18: 2 | L18: 2 | M18: 2 | N18: 2 | O18: 12 | P18: 30.2 | Q18: 78.2 | R18: 37.22 | S18: 11 | T18: 137 | U18: 82.4 | V18: 40 | W18: 73 | X18: 14.6 | Y18: 7200 | AA18: 1 | AB18: 2 | AC18: 2 | AD18: 1 | AE18: 2 | AF18: 0 | AG18: 1 | AH18: 1 | AI18: 2 | AK18: 4 | AN18: 85 | AO18: 0 | AP18: 0 | AQ18: 0 | AR18: 0 | AS18: 0 | AT18: 0 | AU18: 0 | AV18: 1 | AW18: 2 | AX18: 2 | AY18: 0 | AZ18: 0 | BA18: 0 | BB18: 1 | BC18: 6 | BD18: 1 | BE18: 1 | BF18: 0 | BG18: 0
A19: Suman G. Yadav | B19: 70 | C19: 2 | D19: 19 | E19: 1 | F19: 2 | G19: 2 | H19: 2 | I19: 2 | J19: 2 | K19: 2 | L19: 2 | M19: 2 | N19: 2 | O19: 9.8 | P19: 30.8 | Q19: 96.3 | R19: 7.81 | S19: 6.3 | T19: 128 | U19: 68.8 | V19: 24 | W19: 176 | X19: 35.2 | Y19: 1539 | AA19: 9 | AB19: 2 | AC19: 1 | AD19: 1 | AE19: 4 | AF19: 0 | AG19: 1 | AH19: 1 | AI19: 1 | AJ19: 2 | AL19: 1 | AM19: 2 | AO19: 0 | AP19: 0 | AQ19: 0 | AR19: 0 | AS19: 0 | AT19: 0 | AU19: 0 | AV19: 1 | AW19: 2 | AX19: 2 | AY19: 0 | AZ19: 0 | BA19: 0 | BB19: 1 | BC19: 6 | BD19: 1 | BE19: 1 | BF19: 0 | BG19: 6
A20: Suresh Acharehar | B20: 45 | C20: 1 | D20: 20 | E20: 1 | F20: 1 | G20: 2 | H20: 2 | I20: 2 | J20: 2 | K20: 2 | L20: 2 | M20: 2 | N20: 2 | O20: 13.9 | P20: 43.1 | Q20: 91.6 | R20: 12.63 | S20: 13 | T20: 193 | U20: 124.6 | V20: 39 | W20: 147 | X20: 29.4 | Y20: 192 | AA20: 9 | AB20: 2 | AC20: 1 | AD20: 3 | AE20: 5 | AF20: 0 | AG20: 1 | AH20: 2 | AI20: 1 | AJ20: 1 | AL20: 2 | AM20: 2 | AN20: 100 | AO20: 1 | AP20: 2 | AQ20: 2 | AR20: 2 | AS20: 0 | AT20: 1 | AU20: 1 | AV20: 0 | AW20: 0 | AX20: 0 | AY20: 0 | AZ20: 0 | BA20: 0 | BB20: 0 | BC20: 9 | BD20: 1 | BE20: 1 | BF20: 0 | BG20: 0
A21: Lalbahadur singh | B21: 70 | C21: 1 | D21: 14 | E21: 2 | F21: 2 | G21: 1 | H21: 2 | I21: 1 | J21: 2 | K21: 2 | L21: 2 | M21: 2 | N21: 2 | O21: 13.5 | P21: 41.4 | Q21: 87.6 | R21: 41.69 | S21: 6.9 | T21: 195 | U21: 125.2 | V21: 50 | W21: 99 | X21: 19.8 | Y21: 162 | AA21: 8 | AB21: 2 | AC21: 2 | AD21: 3 | AE21: 4 | AF21: 0 | AG21: 1 | AH21: 2 | AI21: 2 | AL21: 2 | AM21: 2 | AN21: 80 | AO21: 0 | AP21: 2 | AQ21: 2 | AR21: 0 | AS21: 1 | AT21: 1 | AU21: 1 | AV21: 0 | AW21: 0 | AX21: 0 | AY21: 0 | AZ21: 0 | BA21: 0 | BB21: 0 | BC21: 7 | BD21: 1 | BE21: 1 | BF21: 0 | BG21: 0
A22: Varsha Patil/ pawar | B22: 38 | C22: 2 | D22: 17 | E22: 2 | F22: 2 | G22: 2 | H22: 2 | I22: 2 | J22: 2 | K22: 2 | L22: 2 | M22: 2 | N22: 2 | O22: 12 | P22: 35.4 | Q22: 90 | R22: 12.75 | S22: 5.5 | Y22: 166 | AA22: 9 | AB22: 2 | AC22: 2 | AD22: 2 | AE22: 4 | AF22: 0 | AG22: 1 | AI22: 1 | AJ22: 2 | AL22: 2 | AM22: 2 | AN22: 100 | AV22: 1 | AW22: 2 | AX22: 0 | AY22: 2 | AZ22: 1 | BA22: 1 | BB22: 1 | BC22: 8 | BD22: 1 | BE22: 1 | BF22: 1 | BG22: 1
A23: Balasaheb Washilkar | B23: 50 | C23: 1 | D23: 24 | E23: 1 | F23: 2 | G23: 2 | H23: 1 | I23: 2 | J23: 2 | K23: 2 | L23: 2 | M23: 2 | N23: 2 | O23: 13.5 | P23: 41 | Q23: 97.2 | R23: 33.42 | S23: 5.6 | T23: 115 | U23: 64.4 | V23: 31 | W23: 98 | X23: 19.6 | Y23: 156 | AA23: 8 | AB23: 2 | AC23: 1 | AD23: 1 | AE23: 3 | AF23: 0 | AG23: 1 | AH23: 2 | AI23: 1 | AJ23: 1 | AL23: 2 | AM23: 2 | AN23: 25 | AO23: 0 | AP23: 0 | AQ23: 0 | AR23: 0 | AS23: 0 | AT23: 0 | AU23: 0 | AV23: 0 | AW23: 0 | AX23: 0 | AY23: 0 | AZ23: 0 | BA23: 0 | BB23: 1 | BC23: 1 | BD23: 0 | BE23: 1 | BF23: 0 | BG23: 4
A24: Mahavar Bappa | B24: 50 | C24: 1 | D24: 13 | E24: 1 | F24: 2 | G24: 1 | H24: 1 | I24: 1 | J24: 2 | K24: 2 | L24: 2 | M24: 2 | N24: 2 | O24: 11.3 | P24: 32 | Q24: 79 | R24: 44.6 | S24: 5.3 | T24: 195 | U24: 116 | V24: 46 | W24: 162 | X24: 32 | Y24: 148 | AA24: 8 | AB24: 2 | AC24: 1 | AD24: 2 | AE24: 4 | AF24: 0 | AG24: 1 | AH24: 2 | AI24: 2 | AJ24: 2 | AK24: 2 | AL24: 2 | AM24: 2 | AN24: 100 | AO24: 1 | AP24: 2 | AQ24: 0 | AR24: 0 | AS24: 0 | AT24: 0 | AU24: 1 | AV24: 0 | AW24: 0 | AX24: 0 | AY24: 0 | AZ24: 0 | BA24: 0 | BB24: 0 | BC24: 4 | BD24: 1 | BE24: 0 | BF24: 0 | BG24: 0
A25: Lahot Krushna | B25: 74 | C25: 2 | D25: 11 | E25: 1 | F25: 1 | G25: 2 | H25: 2 | I25: 2 | J25: 2 | K25: 2 | L25: 1 | M25: 2 | N25: 2 | O25: 11.8 | P25: 36.7 | Q25: 90.4 | R25: 13.29 | S25: 6.7 | T25: 153 | U25: 96 | V25: 34 | W25: 111 | X25: 22 | Y25: 397 | AA25: 4 | AB25: 2 | AC25: 2 | AD25: 3 | AE25: 3 | AF25: 0 | AG25: 1 | AH25: 1 | AI25: 1 | AJ25: 1 | AK25: 4 | AL25: 2 | AM25: 2 | AN25: 0 | AO25: 0 | AP25: 1 | AQ25: 2 | AR25: 2 | AS25: 1 | AT25: 1 | AU25: 1 | BC25: 8 | BD25: 0 | BE25: 1 | BG25: 6
A26: Anusaya Kharat | B26: 85 | C26: 2 | D26: 21 | E26: 1 | F26: 2 | G26: 2 | H26: 2 | I26: 2 | J26: 2 | K26: 2 | L26: 2 | M26: 2 | N26: 2 | AA26: 7 | AB26: 2 | AC26: 2 | AD26: 1 | AE26: 3 | AF26: 0 | AG26: 1 | AI26: 1 | AJ26: 1 | AK26: 4 | AL26: 2 | AM26: 2 | AN26: 0 | AO26: 0 | AP26: 0 | AQ26: 0 | AR26: 0 | AS26: 0 | AT26: 0 | AU26: 0 | AV26: 0 | AW26: 2 | AX26: 0 | AY26: 0 | AZ26: 0 | BA26: 0 | BB26: 1 | BC26: 3 | BD26: 0 | BE26: 1 | BF26: Bilateral CCA plaques | BG26: 6
A27: Wilson terez | B27: 75 | C27: 2 | D27: 22 | E27: 1 | F27: 1 | G27: 2 | H27: 2 | I27: 2 | J27: 2 | K27: 2 | L27: 2 | M27: 2 | N27: 2 | O27: 10.7 | P27: 32.7 | Q27: 82.6 | R27: 13.7 | Y27: 1136 | AA27: 3 | AB27: 2 | AC27: 2 | AD27: 1 | AE27: 4 | AF27: 0 | AG27: 1 | AH27: 1 | AI27: 2 | AK27: 4 | AL27: 2 | AM27: 2 | AO27: 1 | AP27: 2 | AQ27: 1 | AR27: 2 | AS27: 1 | AT27: 1 | AU27: 1 | AV27: 0 | AW27: 0 | AX27: 0 | AY27: 0 | AZ27: 0 | BA27: 0 | BB27: 0 | BC27: 9 | BD27: 1 | BE27: 1 | BF27: 1 | BG27: 6
A28: Narul Sharma | B28: 26 | C28: 1 | D28: 20 | E28: 2 | F28: 2 | G28: 1 | H28: 1 | I28: 1 | J28: 2 | K28: 2 | L28: 2 | M28: 2 | N28: 2 | O28: 15.7 | P28: 45.2 | Q28: 11.76 | R28: 17.3 | S28: 4.5 | T28: 120 | U28: 66.2 | V28: 36 | W28: 89 | X28: 17.8 | Y28: 148 | AA28: 8 | AB28: 2 | AC28: 1 | AD28: 3 | AE28: 4 | AF28: 0 | AG28: 1 | AH28: 2 | AI28: 1 | AJ28: 1 | AK28: 1 | AL28: 2 | AM28: 2 | AN28: 90 | AO28: 0 | AP28: 0 | AQ28: 0 | AR28: 0 | AS28: 0 | AT28: 0 | AU28: 0 | AV28: 1 | AW28: 2 | AX28: 2 | AY28: 2 | AZ28: 1 | BA28: 1 | BB28: 1 | BC28: 10 | BD28: 1 | BE28: 0 | BF28: Rt CCA thrombus | BG28: 1
A29: Satish Bhalerao | B29: 41 | C29: 1 | D29: 9 | E29: 1 | F29: 1 | G29: 2 | H29: 1 | I29: 2 | J29: 2 | K29: 2 | L29: 2 | M29: 2 | N29: 2 | O29: 15.4 | P29: 43.8 | Q29: 90.6 | R29: 32.46 | S29: 6.1 | T29: 229 | V29: 34 | W29: 553 | Y29: 213 | AA29: 8 | AB29: 2 | AC29: 1 | AD29: 2 | AE29: 5 | AF29: 0 | AG29: 1 | AH29: 1 | AI29: 1 | AJ29: 1 | AK29: 4 | AL29: 2 | AM29: 1 | AN29: 100 | AO29: 1 | AP29: 2 | AQ29: 2 | AR29: 2 | AS29: 1 | AT29: 1 | AU29: 1 | AV29: 0 | AW29: 0 | AX29: 0 | AY29: 0 | AZ29: 0 | BA29: 0 | BB29: 0 | BC29: 10 | BD29: 1 | BE29: 1 | BF29: 0 | BG29: 0
A30: Chandrakant Khopade | B30: 60 | C30: 1 | D30: 18 | E30: 2 | F30: 2 | G30: 2 | H30: 2 | I30: 2 | J30: 2 | K30: 1 | L30: 2 | M30: 2 | N30: 2 | O30: 14 | P30: 32 | Q30: 95 | R30: 22 | S30: 5.5 | Y30: 171 | AA30: 3 | AB30: 2 | AC30: 2 | AD30: 1 | AE30: 3 | AF30: 0 | AG30: 1 | AH30: 2 | AI30: 1 | AJ30: 1 | AK30: 3 | AN30: 30 | AO30: 1 | AP30: 2 | AQ30: 2 | AR30: 0 | AS30: 1 | AT30: 1 | AU30: 1 | AV30: 0 | AW30: 0 | AX30: 0 | AY30: 0 | AZ30: 0 | BA30: 0 | BB30: 0 | BC30: 8 | BD30: 1 | BE30: 1 | BF30: 0 | BG30: 4
A31: Kiran shinde | B31: 45 | C31: 1 | D31: 12 | E31: 2 | F31: 2 | G31: 1 | H31: 1 | I31: 2 | J31: 2 | K31: 2 | L31: 2 | M31: 2 | N31: 2 | O31: 16 | P31: 48.3 | Q31: 99.6 | R31: 16.74 | S31: 4.5 | T31: 125 | U31: 66.8 | V31: 48 | W31: 51 | X31: 10.2 | Y31: 151 | AA31: 8 | AB31: 2 | AC31: 2 | AD31: 2 | AE31: 2 | AF31: 0 | AG31: 1 | AH31: 1 | AI31: 1 | AJ31: 1 | AL31: 1 | AM31: 1 | AN31: 45 | AO31: 0 | AP31: 0 | AQ31: 0 | AR31: 0 | AS31: 1 | AT31: 1 | AU31: 1 | AV31: 0 | AW31: 0 | AX31: 0 | AY31: 0 | AZ31: 0 | BA31: 0 | BB31: 0 | BC31: 3 | BD31: 1 | BE31: 0 | BF31: 0 | BG31: 4
A32: Parvati Saste | B32: 57 | C32: 2 | D32: 21 | E32: 2 | F32: 2 | G32: 2 | H32: 2 | I32: 2 | J32: 2 | K32: 1 | L32: 2 | M32: 2 | N32: 2 | O32: 14.4 | P32: 43 | Q32: 97.3 | AA32: 3 | AB32: 2 | AC32: 1 | AD32: 3 | AE32: 4 | AF32: 0 | AG32: 1 | AH32: 2 | AI32: 2 | AL32: 2 | AM32: 2 | AN32: 0 | AO32: 0 | AP32: 0 | AQ32: 0 | AR32: 0 | AS32: 0 | AT32: 0 | AU32: 0 | AV32: 1 | AW32: 2 | AX32: 2 | AY32: 1 | AZ32: 1 | BA32: 1 | BB32: 1 | BC32: 9 | BD32: 0 | BE32: 1 | BF32: Lt CCA Plaque | BG32: 6
A33: Anita Yedge | B33: 39 | C33: 2 | D33: 22 | E33: 2 | F33: 2 | G33: 2 | H33: 2 | I33: 2 | J33: 2 | K33: 2 | L33: 2 | M33: 2 | N33: 2 | O33: 12 | R33: 4.65 | S33: 5.9 | T33: 105 | U33: 126.2 | V33: 47 | W33: 109 | X33: 4.8 | AA33: 5 | AB33: 2 | AC33: 2 | AD33: 1 | AE33: 4 | AF33: 0 | AG33: 1 | AH33: 2 | AI33: 2 | AL33: 2 | AM33: 1 | AN33: 60 | AV33: 0 | AW33: 0 | AX33: 0 | AY33: 0 | AZ33: 1 | BA33: 1 | BB33: 1 | BC33: 3 | BD33: 0 | BE33: 1 | BF33: Lt ICA occluded | BG33: 3
A34: Ramchandra Pangarkar | B34: 48 | C34: 1 | D34: 20 | K34: 1 | L34: 1 | M34: 1 | N34: 1 | O34: 11 | Q34: 77 | R34: 21 | Y34: 410 | AA34: 3 | AB34: 2 | AC34: 2 | AD34: 2 | AE34: 3 | AF34: 0 | AG34: 1 | AI34: 2 | AK34: 4 | AN34: 0 | AO34: 0 | AP34: 0 | AQ34: 0 | AR34: 0 | AS34: 0 | AT34: 0 | AU34: 0 | AV34: 1 | AW34: 2 | AX34: 2 | AY34: 0 | AZ34: 0 | BA34: 0 | BB34: 1 | BC34: 6 | BD34: 1 | BE34: 1 | BF34: 0 | BG34: 6
A35: Arun Rale | B35: 63 | C35: 1 | D35: 14 | E35: 1 | F35: 2 | G35: 2 | H35: 2 | I35: 2 | J35: 2 | K35: 2 | L35: 2 | M35: 2 | N35: 2 | O35: 13.3 | R35: 14.94 | S35: 5.8 | T35: 212 | U35: 123.4 | V35: 66 | W35: 113 | X35: 22.6 | AA35: 8 | AB35: 2 | AC35: 1 | AD35: 4 | AE35: 5 | AF35: 0 | AG35: 1 | AH35: 1 | AI35: 2 | AK35: 4 | AL35: 2 | AM35: 2 | AN35: 95 | AV35: 1 | AW35: 2 | AX35: 1 | AY35: 2 | AZ35: 1 | BA35: 1 | BB35: 1 | BC35: 9 | BD35: 1 | BE35: 1 | BF35: 1 | BG35: 1
A36: Kamlabai Kumbhar | B36: 65 | C36: 2 | D36: 10 | E36: 2 | F36: 1 | G36: 2 | H36: 2 | I36: 2 | J36: 2 | K36: 2 | L36: 2 | M36: 2 | N36: 2 | O36: 13 | P36: 39.7 | R36: 6.51 | S36: 14.3 | T36: 198 | U36: 109.2 | V36: 29 | W36: 299 | Y36: 413 | AA36: 7 | AB36: 2 | AC36: 1 | AD36: 2 | AE36: 4 | AF36: 0 | AG36: 1 | AH36: 1 | AI36: 2 | AK36: 4 | AL36: 2 | AM36: 2 | AN36: 100 | AO36: 1 | AP36: 2 | AQ36: 2 | AR36: 2 | AS36: 1 | AT36: 1 | AU36: 1 | BC36: 10 | BD36: 1 | BE36: 1 | BG36: 0
A37: Tukaram Potdar | B37: 76 | C37: 1 | D37: 13 | E37: 1 | F37: 2 | G37: 2 | H37: 1 | I37: 2 | J37: 2 | K37: 2 | L37: 2 | M37: 2 | N37: 2 | O37: 13.1 | S37: 5.7 | T37: 175 | U37: 112.4 | V37: 36 | W37: 133 | X37: 26.6 | Y37: 332 | Z37: 61 | AA37: 9 | AB37: 3 | AC37: 1 | AD37: 3 | AE37: 5 | AF37: 1 | AG37: 1 | AH37: 2 | AI37: 1 | AJ37: 1 | AL37: 2 | AM37: 2 | AO37: 0 | AP37: 1 | AQ37: 1 | AR37: 2 | AS37: 1 | AT37: 1 | AU37: 1 | AV37: 0 | AW37: 0 | AX37: 0 | AY37: 0 | AZ37: 0 | BA37: 0 | BB37: 0 | BC37: 7 | BD37: 1 | BE37: 0 | BF37: Right CCA plaque | BG37: 6
A38: Ratnmala A Gaikwad | B38: 68 | C38: 2 | D38: 0 | E38: 1 | F38: 2 | G38: 2 | H38: 2 | I38: 2 | J38: 2 | K38: 2 | L38: 2 | M38: 2 | N38: 2 | O38: 10.8 | P38: 33.9 | Q38: 13.6 | R38: 6.18 | S38: 6.9 | T38: 239 | U38: 156.4 | V38: 48 | W38: 173 | X38: 34.6 | Y38: 1560 | AA38: 10 | AB38: 3 | AC38: 1 | AD38: 3 | AE38: 5 | AF38: 1 | AG38: 1 | AH38: 1 | AI38: 2 | AL38: 2 | AM38: 2 | AN38: 70 | AO38: 1 | AP38: 2 | AQ38: 2 | AR38: 0 | AS38: 1 | AT38: 1 | AU38: 1 | AV38: 0 | AW38: 0 | AX38: 0 | AY38: 0 | AZ38: 0 | BA38: 0 | BB38: 0 | BC38: 8 | BD38: 1 | BE38: 1 | BF38: 0 | BG38: 2
A39: Devendra Sigh | B39: 54 | C39: 1 | D39: 3 | E39: 1 | F39: 2 | G39: 1 | H39: 1 | I39: 1 | J39: 2 | K39: 2 | L39: 2 | M39: 2 | N39: 2 | O39: 16 | P39: 47.2 | Q39: 96.7 | R39: 16.26 | S39: 5.4 | Y39: 178 | AA39: 8 | AB39: 3 | AC39: 1 | AD39: 3 | AE39: 5 | AF39: 1 | AG39: 1 | AH39: 1 | AI39: 2 | AL39: 2 | AM39: 2 | AN39: 100 | AO39: 0 | AP39: 0 | AQ39: 0 | AR39: 0 | AS39: 0 | AT39: 0 | AU39: 0 | AV39: 0 | AW39: 2 | AX39: 2 | AY39: 2 | AZ39: 1 | BA39: 1 | BB39: 1 | BC39: 9 | BD39: 1 | BE39: 1 | BF39: 0 | BG39: 0
A40: Prabhavati Bhargvde | B40: 75 | C40: 2 | D40: 2 | E40: 1 | F40: 1 | G40: 2 | H40: 1 | I40: 2 | J40: 2 | K40: 2 | L40: 2 | M40: 2 | N40: 2 | O40: 9.22 | P40: 33.5 | Q40: 82.2 | R40: 17 | S40: 6.1 | T40: 132 | U40: 78 | V40: 42 | W40: 58 | X40: 11.6 | Y40: 576 | AA40: 10 | AB40: 3 | AC40: 1 | AD40: 3 | AE40: 5 | AF40: 1 | AG40: 1 | AH40: 1 | AI40: 2 | AK40: 4 | AL40: 2 | AM40: 2 | AN40: 100 | AO40: 1 | AP40: 2 | AQ40: 2 | AR40: 2 | AS40: 1 | AT40: 1 | AU40: 1 | AV40: 0 | AW40: 0 | AX40: 0 | AY40: 0 | AZ40: 0 | BA40: 0 | BB40: 0 | BC40: 10 | BD40: 1 | BE40: 0 | BF40: Bilateral CCA plaque | BG40: 0
...

Sheet Collateral Calc
A1: Mass | B1: TAN | C1: MIFFECT | D1: MCT Angio
A2: TAN | B2: MAS | C2: MITEFF | D2: MCTA
A3: V39 | B3: V41 | C3: V40 | D3: V42 | E3: COLLATERAL | F3: TAN | G3: MAS | H3: MITEFF | I3: MCTA
A4: 1 | B4: 2 | C4: 1 | D4: 4 | E4: =IF(OR((A4=2), (B4<=2),(C4<=2),(D4<=3)),"Poor","Good") -> Poor | F4: =IF(A4=2,"Poor","Good") -> Good | G4: =IF(B4<=2,"Poor","Good") -> Poor | H4: =IF(C4<=2,"Poor","Good") -> Poor | I4: =IF(D4<=3,"Poor","Good") -> Good
A5: 1 | B5: 2 | C5: 2 | D5: 2 | E5: =IF(OR((A5=2), (B5<=2),(C5<=2),(D5<=3)),"Poor","Good") -> Poor | F5: =IF(A5=2,"Poor","Good") -> Good | G5: =IF(B5<=2,"Poor","Good") -> Poor | H5: =IF(C5<=2,"Poor","Good") -> Poor | I5: =IF(D5<=3,"Poor","Good") -> Poor
A6: 1 | B6: 2 | C6: 1 | D6: 1 | E6: =IF(OR((A6=2), (B6<=2),(C6<=2),(D6<=3)),"Poor","Good") -> Poor | F6: =IF(A6=2,"Poor","Good") -> Good | G6: =IF(B6<=2,"Poor","Good") -> Poor | H6: =IF(C6<=2,"Poor","Good") -> Poor | I6: =IF(D6<=3,"Poor","Good") -> Poor
A7: 1 | B7: 2 | C7: 1 | D7: 1 | E7: =IF(OR((A7=2), (B7<=2),(C7<=2),(D7<=3)),"Poor","Good") -> Poor | F7: =IF(A7=2,"Poor","Good") -> Good | G7: =IF(B7<=2,"Poor","Good") -> Poor | H7: =IF(C7<=2,"Poor","Good") -> Poor | I7: =IF(D7<=3,"Poor","Good") -> Poor
A8: 2 | B8: 1 | C8: 2 | D8: 5 | E8: =IF(OR((A8=2), (B8<=2),(C8<=2),(D8<=3)),"Poor","Good") -> Poor | F8: =IF(A8=2,"Poor","Good") -> Poor | G8: =IF(B8<=2,"Poor","Good") -> Poor | H8: =IF(C8<=2,"Poor","Good") -> Poor | I8: =IF(D8<=3,"Poor","Good") -> Good
A9: 2 | B9: 1 | C9: 2 | D9: 4 | E9: =IF(OR((A9=2), (B9<=2),(C9<=2),(D9<=3)),"Poor","Good") -> Poor | F9: =IF(A9=2,"Poor","Good") -> Poor | G9: =IF(B9<=2,"Poor","Good") -> Poor | H9: =IF(C9<=2,"Poor","Good") -> Poor | I9: =IF(D9<=3,"Poor","Good") -> Good
A10: 2 | B10: 1 | C10: 3 | D10: 4 | E10: =IF(OR((A10=2), (B10<=2),(C10<=2),(D10<=3)),"Poor","Good") -> Poor | F10: =IF(A10=2,"Poor","Good") -> Poor | G10: =IF(B10<=2,"Poor","Good") -> Poor | H10: =IF(C10<=2,"Poor","Good") -> Good | I10: =IF(D10<=3,"Poor","Good") -> Good
A11: 2 | B11: 2 | C11: 2 | D11: 3 | E11: =IF(OR((A11=2), (B11<=2),(C11<=2),(D11<=3)),"Poor","Good") -> Poor | F11: =IF(A11=2,"Poor","Good") -> Poor | G11: =IF(B11<=2,"Poor","Good") -> Poor | H11: =IF(C11<=2,"Poor","Good") -> Poor | I11: =IF(D11<=3,"Poor","Good") -> Poor
A12: 2 | B12: 2 | C12: 1 | D12: 4 | E12: =IF(OR((A12=2), (B12<=2),(C12<=2),(D12<=3)),"Poor","Good") -> Poor | F12: =IF(A12=2,"Poor","Good") -> Poor | G12: =IF(B12<=2,"Poor","Good") -> Poor | H12: =IF(C12<=2,"Poor","Good") -> Poor | I12: =IF(D12<=3,"Poor","Good") -> Good
A13: 2 | B13: 2 | C13: 3 | D13: 4 | E13: =IF(OR((A13=2), (B13<=2),(C13<=2),(D13<=3)),"Poor","Good") -> Poor | F13: =IF(A13=2,"Poor","Good") -> Poor | G13: =IF(B13<=2,"Poor","Good") -> Poor | H13: =IF(C13<=2,"Poor","Good") -> Good | I13: =IF(D13<=3,"Poor","Good") -> Good
A14: 2 | B14: 1 | C14: 3 | D14: 4 | E14: =IF(OR((A14=2), (B14<=2),(C14<=2),(D14<=3)),"Poor","Good") -> Poor | F14: =IF(A14=2,"Poor","Good") -> Poor | G14: =IF(B14<=2,"Poor","Good") -> Poor | H14: =IF(C14<=2,"Poor","Good") -> Good | I14: =IF(D14<=3,"Poor","Good") -> Good
A15: 2 | B15: 2 | C15: 2 | D15: 4 | E15: =IF(OR((A15=2), (B15<=2),(C15<=2),(D15<=3)),"Poor","Good") -> Poor | F15: =IF(A15=2,"Poor","Good") -> Poor | G15: =IF(B15<=2,"Poor","Good") -> Poor | H15: =IF(C15<=2,"Poor","Good") -> Poor | I15: =IF(D15<=3,"Poor","Good") -> Good
... A133: 1 | B133: 3 | C133: 3 | D133: 4 | E133: =IF(OR((A133=2), (B133<=2),(C133<=2),(D133<=3)),"Poor","Good") -> Good | F133: =IF(A133=2,"Poor","Good") -> Good | G133: =IF(B133<=2,"Poor","Good") -> Good | H133: =IF(C133<=2,"Poor","Good") -> Good | I133: =IF(D133<=3,"Poor","Good") -> Good
A134: 2 | B134: 3 | C134: 1 | E134: =IF(OR((A134=2), (B134<=2),(C134<=2),(D134<=3)),"Poor","Good") -> Poor | F134: =IF(A134=2,"Poor","Good") -> Poor | G134: =IF(B134<=2,"Poor","Good") -> Good | H134: =IF(C134<=2,"Poor","Good") -> Poor | I134: =IF(D134<=3,"Poor","Good") -> Poor
A135: 1 | B135: 3 | C135: 2 | D135: 5 | E135: =IF(OR((A135=2), (B135<=2),(C135<=2),(D135<=3)),"Poor","Good") -> Poor | F135: =IF(A135=2,"Poor","Good") -> Good | G135: =IF(B135<=2,"Poor","Good") -> Good | H135: =IF(C135<=2,"Poor","Good") -> Poor | I135: =IF(D135<=3,"Poor","Good") -> Good
A136: 1 | B136: 3 | C136: 3 | D136: 5 | E136: =IF(OR((A136=2), (B136<=2),(C136<=2),(D136<=3)),"Poor","Good") -> Good | F136: =IF(A136=2,"Poor","Good") -> Good | G136: =IF(B136<=2,"Poor","Good") -> Good | H136: =IF(C136<=2,"Poor","Good") -> Good | I136: =IF(D136<=3,"Poor","Good") -> Good
A137: 1 | B137: 3 | C137: 3 | D137: 5 | E137: =IF(OR((A137=2), (B137<=2),(C137<=2),(D137<=3)),"Poor","Good") -> Good | F137: =IF(A137=2,"Poor","Good") -> Good | G137: =IF(B137<=2,"Poor","Good") -> Good | H137: =IF(C137<=2,"Poor","Good") -> Good | I137: =IF(D137<=3,"Poor","Good") -> Good
A138: 2 | B138: 3 | C138: 3 | D138: 5 | E138: =IF(OR((A138=2), (B138<=2),(C138<=2),(D138<=3)),"Poor","Good") -> Poor | F138: =IF(A138=2,"Poor","Good") -> Poor | G138: =IF(B138<=2,"Poor","Good") -> Good | H138: =IF(C138<=2,"Poor","Good") -> Good | I138: =IF(D138<=3,"Poor","Good") -> Good
A139: 1 | B139: 3 | C139: 3 | D139: 5 | E139: =IF(OR((A139=2), (B139<=2),(C139<=2),(D139<=3)),"Poor","Good") -> Good | F139: =IF(A139=2,"Poor","Good") -> Good | G139: =IF(B139<=2,"Poor","Good") -> Good | H139: =IF(C139<=2,"Poor","Good") -> Good | I139: =IF(D139<=3,"Poor","Good") -> Good
A140: 1 | B140: 3 | C140: 3 | D140: 5 | E140: =IF(OR((A140=2), (B140<=2),(C140<=2),(D140<=3)),"Poor","Good") -> Good | F140: =IF(A140=2,"Poor","Good") -> Good | G140: =IF(B140<=2,"Poor","Good") -> Good | H140: =IF(C140<=2,"Poor","Good") -> Good | I140: =IF(D140<=3,"Poor","Good") -> Good
A141: 1 | B141: 3 | C141: 3 | D141: 5 | E141: =IF(OR((A141=2), (B141<=2),(C141<=2),(D141<=3)),"Poor","Good") -> Good | F141: =IF(A141=2,"Poor","Good") -> Good | G141: =IF(B141<=2,"Poor","Good") -> Good | H141: =IF(C141<=2,"Poor","Good") -> Good | I141: =IF(D141<=3,"Poor","Good") -> Good
A142: 1 | B142: 3 | C142: 3 | D142: 5 | E142: =IF(OR((A142=2), (B142<=2),(C142<=2),(D142<=3)),"Poor","Good") -> Good | F142: =IF(A142=2,"Poor","Good") -> Good | G142: =IF(B142<=2,"Poor","Good") -> Good | H142: =IF(C142<=2,"Poor","Good") -> Good | I142: =IF(D142<=3,"Poor","Good") -> Good
A143: 1 | B143: 3 | C143: 3 | D143: 5 | E143: =IF(OR((A143=2), (B143<=2),(C143<=2),(D143<=3)),"Poor","Good") -> Good | F143: =IF(A143=2,"Poor","Good") -> Good | G143: =IF(B143<=2,"Poor","Good") -> Good | H143: =IF(C143<=2,"Poor","Good") -> Good | I143: =IF(D143<=3,"Poor","Good") -> Good
A144: 1 | B144: 3 | C144: 3 | D144: 5 | E144: =IF(OR((A144=2), (B144<=2),(C144<=2),(D144<=3)),"Poor","Good") -> Good | F144: =IF(A144=2,"Poor","Good") -> Good | G144: =IF(B144<=2,"Poor","Good") -> Good | H144: =IF(C144<=2,"Poor","Good") -> Good | I144: =IF(D144<=3,"Poor","Good") -> Good
A145: 1 | B145: 3 | C145: 3 | D145: 5 | E145: =IF(OR((A145=2), (B145<=2),(C145<=2),(D145<=3)),"Poor","Good") -> Good | F145: =IF(A145=2,"Poor","Good") -> Good | G145: =IF(B145<=2,"Poor","Good") -> Good | H145: =IF(C145<=2,"Poor","Good") -> Good | I145: =IF(D145<=3,"Poor","Good") -> Good
B146: 3 | C146: 3 | D146: 5 | E146: =IF(OR((A146=2), (B146<=2),(C146<=2),(D146<=3)),"Poor","Good") -> Good | F146: =IF(A146=2,"Poor","Good") -> Good | G146: =IF(B146<=2,"Poor","Good") -> Good | H146: =IF(C146<=2,"Poor","Good") -> Good | I146: =IF(D146<=3,"Poor","Good") -> Good
A147: 1 | B147: 3 | C147: 3 | D147: 5 | E147: =IF(OR((A147=2), (B147<=2),(C147<=2),(D147<=3)),"Poor","Good") -> Good | F147: =IF(A147=2,"Poor","Good") -> Good | G147: =IF(B147<=2,"Poor","Good") -> Good | H147: =IF(C147<=2,"Poor","Good") -> Good | I147: =IF(D147<=3,"Poor","Good") -> Good
A148: 1 | B148: 3 | C148: 3 | D148: 5 | E148: =IF(OR((A148=2), (B148<=2),(C148<=2),(D148<=3)),"Poor","Good") -> Good | F148: =IF(A148=2,"Poor","Good") -> Good | G148: =IF(B148<=2,"Poor","Good") -> Good | H148: =IF(C148<=2,"Poor","Good") -> Good | I148: =IF(D148<=3,"Poor","Good") -> Good
A149: 1 | B149: 3 | C149: 3 | D149: 5 | E149: =IF(OR((A149=2), (B149<=2),(C149<=2),(D149<=3)),"Poor","Good") -> Good | F149: =IF(A149=2,"Poor","Good") -> Good | G149: =IF(B149<=2,"Poor","Good") -> Good | H149: =IF(C149<=2,"Poor","Good") -> Good | I149: =IF(D149<=3,"Poor","Good") -> Good
A150: 1 | B150: 4 | C150: 3 | D150: 5 | E150: =IF(OR((A150=2), (B150<=2),(C150<=2),(D150<=3)),"Poor","Good") -> Good | F150: =IF(A150=2,"Poor","Good") -> Good | G150: =IF(B150<=2,"Poor","Good") -> Good | H150: =IF(C150<=2,"Poor","Good") -> Good | I150: =IF(D150<=3,"Poor","Good") -> Good
A151: 1 | B151: 4 | C151: 3 | D151: 5 | E151: =IF(OR((A151=2), (B151<=2),(C151<=2),(D151<=3)),"Poor","Good") -> Good | F151: =IF(A151=2,"Poor","Good") -> Good | G151: =IF(B151<=2,"Poor","Good") -> Good | H151: =IF(C151<=2,"Poor","Good") -> Good | I151: =IF(D151<=3,"Poor","Good") -> Good
A152: 1 | B152: 4 | C152: 3 | D152: 5 | E152: =IF(OR((A152=2), (B152<=2),(C152<=2),(D152<=3)),"Poor","Good") -> Good | F152: =IF(A152=2,"Poor","Good") -> Good | G152: =IF(B152<=2,"Poor","Good") -> Good | H152: =IF(C152<=2,"Poor","Good") -> Good | I152: =IF(D152<=3,"Poor","Good") -> Good
A153: 1 | B153: 4 | C153: 3 | D153: 5 | E153: =IF(OR((A153=2), (B153<=2),(C153<=2),(D153<=3)),"Poor","Good") -> Good | F153: =IF(A153=2,"Poor","Good") -> Good | G153: =IF(B153<=2,"Poor","Good") -> Good | H153: =IF(C153<=2,"Poor","Good") -> Good | I153: =IF(D153<=3,"Poor","Good") -> Good
A154: 1 | B154: 4 | C154: 3 | D154: 5 | E154: =IF(OR((A154=2), (B154<=2),(C154<=2),(D154<=3)),"Poor","Good") -> Good | F154: =IF(A154=2,"Poor","Good") -> Good | G154: =IF(B154<=2,"Poor","Good") -> Good | H154: =IF(C154<=2,"Poor","Good") -> Good | I154: =IF(D154<=3,"Poor","Good") -> Good
A155: 1 | B155: 4 | C155: 3 | D155: 5 | E155: =IF(OR((A155=2), (B155<=2),(C155<=2),(D155<=3)),"Poor","Good") -> Good | F155: =IF(A155=2,"Poor","Good") -> Good | G155: =IF(B155<=2,"Poor","Good") -> Good | H155: =IF(C155<=2,"Poor","Good") -> Good | I155: =IF(D155<=3,"Poor","Good") -> Good
A156: 1 | B156: 4 | C156: 3 | D156: 5 | E156: =IF(OR((A156=2), (B156<=2),(C156<=2),(D156<=3)),"Poor","Good") -> Good | F156: =IF(A156=2,"Poor","Good") -> Good | G156: =IF(B156<=2,"Poor","Good") -> Good | H156: =IF(C156<=2,"Poor","Good") -> Good | I156: =IF(D156<=3,"Poor","Good") -> Good
A157: 1 | B157: 4 | C157: 3 | D157: 5 | E157: =IF(OR((A157=2), (B157<=2),(C157<=2),(D157<=3)),"Poor","Good") -> Good | F157: =IF(A157=2,"Poor","Good") -> Good | G157: =IF(B157<=2,"Poor","Good") -> Good | H157: =IF(C157<=2,"Poor","Good") -> Good | I157: =IF(D157<=3,"Poor","Good") -> Good
...

Sheet CORREL-MRS-CBS-NIHSS
B1: clot burden score | C1: MRS | D1: NIHSS
A2: clot burden score | B2: 1
A3: MRS | B3: -0.25611413 | C3: 1
A4: NIHSS | B4: -0.38589677 | C4: 0.48122979 | D4: 1 | J4: PEARSON COEFFICIENT | K4: SAMPLE SIZE | L4: t SCORE | M4: p VALUE
I5: CBS vs MRS | J5: 0.25611413 | K5: 240 | L5: =J5*SQRT(K5-2)/SQRT(1-J5^2) -> 4.0874675 | M5: =_xlfn.T.DIST.2T(L5,K5-2) -> 5.9662002e-05
I6: CBS vs NIHSS | J6: 0.38589677 | K6: 240 | L6: =J6*SQRT(K6-2)/SQRT(1-J6^2) -> 6.4531757 | M6: =_xlfn.T.DIST.2T(L6,K6-2) -> 6.0761806e-10
I7: NIHSS vs MRS | J7: 0.48122979 | K7: 240 | L7: =J7*SQRT(K7-2)/SQRT(1-J7^2) -> 8.4691973 | M7: =_xlfn.T.DIST.2T(L7,K7-2) -> 2.5770913e-15

Sheet Sheet9
A3: Count of Collaterals | B3: Column Labels
A4: Row Labels | B4: Good | C4: Poor | D4: Grand Total | F4: Good | G4: Poor
A5: Good | B5: 116 | C5: 19 | D5: 135 | F5: =142*135/184 -> 104.18478 | G5: =135*42/184 -> 30.815217 | H5: =SUM(F5+G5) -> 135
A6: Poor | B6: 26 | C6: 23 | D6: 49 | F6: =49*142/184 -> 37.815217 | G6: =49*42/184 -> 11.184783 | H6: =SUM(F6+G6) -> 49
A7: Grand Total | B7: 142 | C7: 42 | D7: 184 | F7: =SUM(F5+F6) -> 142 | G7: =SUM(G5+G6) -> 42 | H7: =SUM(H5+H6) -> 184

Sheet CHI SQ CALC
D7: OBSERVED | I7: EXPECTED
D8: Good MRS | E8: Poor MRS | F8: Grand Total | I8: Good MRS | J8: Poor MRS | K8: Total | N8: Good MRS | O8: Poor MRS
C9: Good Collateral | D9: 116 | E9: 19 | F9: 135 | H9: Good Collateral | I9: 104.18478 | J9: 30.815217 | K9: 135 | M9: Good Collateral | N9: =(D9-I9)^2/I9 -> 1.3399208 | O9: =(E9-J9)^2/J9 -> 4.5302086
C10: Poor Collateral | D10: 26 | E10: 23 | F10: 49 | H10: Poor Collateral | I10: 37.815217 | J10: 11.184783 | K10: 49 | M10: Poor Collateral | N10: =(D10-I10)^2/I10 -> 3.6916187 | O10: =(E10-J10)^2/J10 -> 12.481187
C11: Grand Total | D11: 142 | E11: 42 | F11: 184 | I11: 142 | J11: 42 | K11: 184
L14: Chi-sq | N14: =SUM(N9:O10) -> 22.042935
L15: DF | N15: 1
L16: p-value | N16: =_xlfn.CHISQ.DIST.RT(N14,N15) -> 2.6661923e-06
N18: =_xlfn.CHISQ.TEST(D9:E10,I9:J10) -> 2.6661923e-06

Sheet Chi Sq raw
A2: Collaterals | B2: MRS Grading
A3: Poor | B3: Good
A4: Poor | B4: Good
A5: Poor | B5: Poor
A6: Poor | B6: Poor
A7: Poor | B7: Good
A8: Poor | B8: Good
A9: Poor | B9: Good
A10: Poor | B10: Poor
A11: Poor | B11: Good
A12: Poor | B12: Poor
A13: Poor | B13: Poor
... A186: Good | B186: Good

Sheet Correl - raw data
A1: Cerebral collaterals | B1: ='Dr Dulari Data Entry_21_feb_202'!#REF! -> #REF! | C1: MRS | D1: NIHSS
A2: ='Dr Dulari Data Entry_21_feb_202'!AF2 -> 0 | B2: ='Dr Dulari Data Entry_21_feb_202'!BC2 -> 3 | C2: ='Dr Dulari Data Entry_21_feb_202'!BG2 -> 1 | D2: ='Dr Dulari Data Entry_21_feb_202'!D2 -> 22
A3: ='Dr Dulari Data Entry_21_feb_202'!AF3 -> 0 | B3: ='Dr Dulari Data Entry_21_feb_202'!BC3 -> 7 | C3: ='Dr Dulari Data Entry_21_feb_202'!BG3 -> 0 | D3: ='Dr Dulari Data Entry_21_feb_202'!D3 -> 3
A4: ='Dr Dulari Data Entry_21_feb_202'!AF4 -> 0 | B4: ='Dr Dulari Data Entry_21_feb_202'!BC4 -> 3 | C4: ='Dr Dulari Data Entry_21_feb_202'!BG4 -> 6 | D4: ='Dr Dulari Data Entry_21_feb_202'!D4 -> 22
A5: ='Dr Dulari Data Entry_21_feb_202'!AF5 -> 0 | B5: ='Dr Dulari Data Entry_21_feb_202'!BC5 -> 7 | C5: ='Dr Dulari Data Entry_21_feb_202'!BG5 -> 6 | D5: ='Dr Dulari Data Entry_21_feb_202'!D5 -> 0
A6: ='Dr Dulari Data Entry_21_feb_202'!AF6 -> 0 | B6: ='Dr Dulari Data Entry_21_feb_202'!BC6 -> 9 | C6: ='Dr Dulari Data Entry_21_feb_202'!BG6 -> 2 | D6: ='Dr Dulari Data Entry_21_feb_202'!D6 -> 16
A7: ='Dr Dulari Data Entry_21_feb_202'!AF7 -> 0 | B7: ='Dr Dulari Data Entry_21_feb_202'!BC7 -> 8 | C7: ='Dr Dulari Data Entry_21_feb_202'!BG7 -> 0 | D7: ='Dr Dulari Data Entry_21_feb_202'!D7 -> 3
A8: ='Dr Dulari Data Entry_21_feb_202'!AF8 -> 0 | B8: ='Dr Dulari Data Entry_21_feb_202'!BC8 -> 9 | C8: ='Dr Dulari Data Entry_21_feb_202'!BG8 -> 0 | D8: ='Dr Dulari Data Entry_21_feb_202'!D8 -> 0
A9: ='Dr Dulari Data Entry_21_feb_202'!AF9 -> 0 | B9: ='Dr Dulari Data Entry_21_feb_202'!BC9 -> 9 | C9: ='Dr Dulari Data Entry_21_feb_202'!BG9 -> 3 | D9: ='Dr Dulari Data Entry_21_feb_202'!D9 -> 20
A10: ='Dr Dulari Data Entry_21_feb_202'!AF10 -> 0 | B10: ='Dr Dulari Data Entry_21_feb_202'!BC10 -> 7 | C10: ='Dr Dulari Data Entry_21_feb_202'!BG10 -> 0 | D10: ='Dr Dulari Data Entry_21_feb_202'!D10 -> 3
A11: ='Dr Dulari Data Entry_21_feb_202'!AF11 -> 0 | B11: ='Dr Dulari Data Entry_21_feb_202'!BC11 -> 9 | C11: ='Dr Dulari Data Entry_21_feb_202'!BG11 -> 6 | D11: ='Dr Dulari Data Entry_21_feb_202'!D11 -> 7
A12: ='Dr Dulari Data Entry_21_feb_202'!AF12 -> 0 | B12: ='Dr Dulari Data Entry_21_feb_202'!BC12 -> 8 | C12: ='Dr Dulari Data Entry_21_feb_202'!BG12 -> 6 | D12: ='Dr Dulari Data Entry_21_feb_202'!D12 -> 12
A13: ='Dr Dulari Data Entry_21_feb_202'!AF13 -> 0 | B13: ='Dr Dulari Data Entry_21_feb_202'!BC13 -> 6 | C13: ='Dr Dulari Data Entry_21_feb_202'!BG13 -> 0 | D13: ='Dr Dulari Data Entry_21_feb_202'!D13 -> 9
... A241: ='Dr Dulari Data Entry_21_feb_202'!AF241 -> 0 | B241: ='Dr Dulari Data Entry_21_feb_202'!BC241 -> 9 | C241: ='Dr Dulari Data Entry_21_feb_202'!BG241 -> 6 | D241: ='Dr Dulari Data Entry_21_feb_202'!D241 -> 0

Sheet MRI MRS CTA completed
A1: =A1:BO1 -> 0 | B1: Name | F1: PRN | G1: Age | H1: Gender | I1: Onset Date | J1: Onset Time | K1: DOA | L1: DOD | M1: Telephone number | O1: NHSS | P1: Hypertension | Q1: Diabetes | R1: Alcohol | S1: Tobacco | T1: Smoker | U1: Dyslipidaemia | V1: Atrial Fibrillation | W1: Ischemic Heart Disease | X1: Rheumatic Heart Disease | Y1: PastH/o Stroke/TIA | Z1: Other risk factors | AA1: Hemoglobin | AB1: PCV | AC1: MCV | AD1: Homocysteine | AE1: HbA1C | AF1: Cholesterol | AG1: LDL Cholesterol | AH1: HDL Cholesterol | AI1: Triglycerides | AJ1: V-LDL | AK1: Vit B12 | AL1: Vit D | AM1: Other Risk Factor | AO1: CT Report | AQ1: CT Angio | AS1: CT Aspects | AT1: Mass | AU1: TAN | AV1: MIFFECT | AW1: MCT Angio | AY1: Endosprin | AZ1: Clopidrogrel | BA1: Thrombolysis | BB1: If Yes | BC1: Anticogulatin | BD1: Mechanical Thromoctomecy | BE1: Decompression Cranioectomy | BF1: MRS | BG1: Barthel Index
A2: UID | B2: Name | C2: Name TRISHA EXCEL | D2: COMPLETE | E2: Stroke volume | F2: PRN | G2: age | H2: gender | I2: date of onset | J2: time of onset | K2: date of admission | L2: date of discharge | M2: cell1 | N2: cell2 | O2: NIHSS | P2: SHT | Q2: DM | R2: Alcohol | S2: tobacco | T2: smoking | U2: dyslipidaemia | V2: atrial fibrillation | W2: IHD | X2: rheumatic heart disease | Y2: past history of stroke/TIA | Z2: other risk factors | AA2: haemoglobin | AB2: PCV | AC2: MCV | AD2: Homocystiene | AE2: HbA1C | AF2: Cholesterol | AG2: LDL Cholesterol | AH2: HDL Cholesterol | AI2: Triglycerides | AJ2: V LDL | AK2: b 12 | AL2: Vit D | AM2: other investigations | AN2: strokevolume | AO2: MRI Brain | AP2: side of infarct | AQ2: CT Angiography | AR2: Rt | AS2: CT ASPECTS | AT2: TAN | AU2: MAS | AV2: MITEFF | AW2: MCTA | AX2: V54 | AY2: ecosprine | AZ2: clopidogril | BA2: thrombolysis | BB2: thrombolytic agent | BC2: anticoagulation | BD2: mechanical thrombectomy | BE2: decompressive hemicranectomy | BF2: MRS | BG2: barthel index | BH2: Rt infraclinoid ICA | BI2: Rt Supraclinoid ICA | BJ2: Rt Proximal M1 MCA | BK2: Rt Distal M1 MCA | BL2: Rt M2MCA rear | BM2: Rt M2 MCA forward | BN2: Rt A1 ACA | BO2: Lt infraclinoid ICA | BP2: Lt Supraclinoid ICA | BQ2: Lt Proximal M1 MCA | BR2: Lt Distal M1 MCA | BS2: Lt M2MCA rear | BT2: Lt M2 MCA forward | BU2: Lt A1 ACA | BV2: clot burden score | BW2: Lt ICA origin | BX2: Rt ICA origin | BY2: CCA
A3: MI | B3: Prakash Deshmukh | C3: Prakash Deshmukh | D3: 0 | E3: 22.6272 | F3: 240000052028 | G3: 72 | H3: 1 | I3: 45456 | J3: 0.70833333 | K3: 45456 | L3: 45468 | M3: 9766846207 | O3: 22 | P3: 1 | Q3: 1 | R3: 2 | S3: 2 | T3: 2 | U3: 2 | V3: 2 | W3: 2 | X3: 2 | Y3: 2 | AA3: 14.5 | AB3: 43.1 | AC3: 87.6 | AD3: 19.56 | AE3: 5.9 | AK3: 186 | AO3: Left MCA infract | AQ3: Left ICA and MCA M1 occlusion paucity of cortical branches of Lt MCA. Mild peripheral opacification of M2 segment and superior division of MCA | AS3: 9 | AT3: 1 | AU3: 2 | AV3: 1 | AW3: 4 | AY3: 1 | AZ3: 2 | BA3: 1 | BB3: 2 | BD3: 1 | BE3: 2 | BF3: 1 | BG3: 85 | BH3: 0 | BI3: 0 | BJ3: 0 | BK3: 0 | BL3: 0 | BM3: 0 | BN3: 0 | BO3: 0 | BP3: 0 | BQ3: 0 | BR3: 0 | BS3: 1 | BT3: 1 | BU3: 1 | BV3: 3 | BW3: 0 | BX3: 1 | BY3: 0
A4: NG | B4: Madhukar Khangute | C4: Khangate Madhukar | D4: 0 | E4: 131.598 | F4: 240000050700 | G4: 82 | H4: 1 | I4: 45452 | J4: 0.41666667 | K4: 45452 | M4: 7058587361 | O4: 22 | P4: 1 | Q4: 1 | R4: 2 | S4: 2 | T4: 2 | U4: 2 | V4: 2 | W4: 1 | X4: 2 | Y4: 2 | Z4: Hypothyrodism | AA4: 15.6 | AB4: 45.9 | AC4: 89.4 | AD4: 9.93 | AE4: 8.2 | AK4: 1335 | AO4: Hyperacute to acute NHI in the Lt MCA and PCA teritory | AQ4: Complete non-opacification of Lt ICA origin atherosclerotic plaque at origin of Lt ICA and carvenous segment of B/L ICAs M1 segment Lt MCA and ACA show opacification | AS4: 9 | AT4: 1 | AU4: 2 | AV4: 1 | AW4: 1 | AY4: 1 | AZ4: 2 | BA4: 1 | BB4: 2 | BD4: 2 | BE4: 2 | BF4: 6 | BG4: 0 | BH4: 0 | BI4: 0 | BJ4: 0 | BK4: 0 | BL4: 0 | BM4: 0 | BN4: 0 | BO4: 1 | BP4: 2 | BQ4: 0 | BR4: 0 | BS4: 0 | BT4: 0 | BU4: 0 | BV4: 3 | BW4: 1 | BX4: 1 | BY4: 0
A5: MY | B5: Nilesh Dhande | C5: Nilesh Dhande | D5: 0 | E5: 73.4947 | F5: 240000049153 | G5: 46 | H5: 1 | I5: 45446 | J5: 0.3125 | K5: 45446 | L5: 45449 | M5: 9822757106 | O5: 3 | P5: 1 | Q5: 2 | R5: 2 | S5: 2 | T5: 2 | U5: 2 | V5: 2 | W5: 2 | X5: 2 | Y5: 2 | AA5: 14.2 | AB5: 43.9 | AC5: 82.6 | AD5: 9 | AE5: 5.5 | AF5: 161 | AG5: 88 | AH5: 46 | AI5: 132 | AJ5: 26 | AO5: hypodensity seen in Lt temporo-parietal lobe S/O acute infract | AQ5: Left ICA carvenous, clinoid, supraclinoid 85-90% luminal narrowing. Thrombus in left superior division M2 complete occlusion of inferior division of left MCA | AS5: 6 | AT5: 1 | AU5: 2 | AV5: 2 | AW5: 2 | AY5: 1 | AZ5: 1 | BA5: 2 | BC5: 3 | BD5: 2 | BE5: 2 | BF5: 0 | BG5: 100 | BH5: 0 | BI5: 0 | BJ5: 0 | BK5: 0 | BL5: 0 | BM5: 0 | BN5: 0 | BO5: 0 | BP5: 0 | BQ5: 2 | BR5: 2 | BS5: 1 | BT5: 1 | BU5: 1 | BV5: 7 | BW5: 1 | BX5: 1 | BY5: 0
A6: BH | B6: Bhalchandra govande | C6: govande balachandra | D6: 0 | E6: 194.168 | F6: 240000079901 | G6: 83 | H6: 1 | I6: 45549 | J6: 0.76388889 | K6: 45549 | L6: 45552 | M6: 9766054422 | P6: 1 | Q6: 1 | R6: 2 | S6: 2 | T6: 2 | U6: 2 | V6: 1 | W6: 2 | X6: 2 | Y6: 1 | Z6: Parkinsons disease, CVA 2023 | AA6: 11.8 | AB6: 42 | AE6: 9.1 | AF6: 120 | AG6: 62 | AH6: 25 | AI6: 165 | AJ6: 33 | AO6: Rt malignat MCA teritory infract | AQ6: Rt M1 Occlusion | AS6: 7 | AT6: 1 | AU6: 2 | AV6: 1 | AW6: 1 | AY6: 1 | AZ6: 2 | BA6: 2 | BC6: 4 | BD6: 2 | BE6: 2 | BF6: 6 | BG6: 0 | BH6: 0 | BI6: 2 | BJ6: 2 | BK6: 0 | BL6: 1 | BM6: 1 | BN6: 1 | BO6: 0 | BP6: 0 | BQ6: 0 | BR6: 0 | BS6: 0 | BT6: 0 | BU6: 0 | BV6: 7 | BW6: 1 | BX6: 1 | BY6: Rt CCA plaque
A7: AF | B7: Balasaheb Washilkar | C7: Namdev Washilkar | D7: 1 | E7: 53.8945 | F7: 24000001332 | G7: 50 | H7: 1 | I7: 45294 | J7: 0.26041667 | K7: 45294 | L7: 45306 | M7: 7822843581 | O7: 24 | P7: 1 | Q7: 2 | R7: 2 | S7: 1 | T7: 2 | U7: 2 | V7: 2 | W7: 2 | X7: 2 | Y7: 2 | Z7: Aspiration pneumonia | AA7: 13.5 | AB7: 41 | AC7: 97.2 | AD7: 33.42 | AE7: 5.6 | AF7: 115 | AG7: 64.4 | AH7: 31 | AI7: 98 | AJ7: 19.6 | AK7: 156 | AQ7: Completer non-opacification of Lt ICA from its origin and Lt MCA suggestive of thrombosis | AS7: 8 | AT7: 2 | AU7: 1 | AV7: 1 | AW7: 3 | AY7: 1 | AZ7: 2 | BA7: 1 | BB7: 1 | BD7: 2 | BE7: 2 | BF7: 4 | BG7: 25 | BH7: 0 | BI7: 0 | BJ7: 0 | BK7: 0 | BL7: 0 | BM7: 0 | BN7: 0 | BO7: 0 | BP7: 0 | BQ7: 0 | BR7: 0 | BS7: 0 | BT7: 0 | BU7: 1 | BV7: 1 | BW7: 0 | BX7: 1 | BY7: 0
A8: AI | B8: Anusaya Kharat | C8: Anusaya Kharat | D8: 0 | E8: 80.183 | F8: 240000013172 | G8: 85 | H8: 2 | I8: 45328 | J8: 0.23125 | K8: 45328 | L8: 45337 | M8: 7058983347 | O8: 21 | P8: 1 | Q8: 2 | R8: 2 | S8: 2 | T8: 2 | U8: 2 | V8: 2 | W8: 2 | X8: 2 | Y8: 2 | Z8: Generalised weakness since 25 days | AO8: Large left MCA infract with mass effect and midline shift 2.2mm to right. | AS8: 7 | AT8: 2 | AU8: 2 | AV8: 1 | AW8: 3 | AY8: 1 | BA8: 1 | BB8: 1 | BC8: 4 | BD8: 2 | BE8: 2 | BF8: 6 | BG8: 0 | BH8: 0 | BI8: 0 | BJ8: 0 | BK8: 0 | BL8: 0 | BM8: 0 | BN8: 0 | BO8: 0 | BP8: 2 | BQ8: 0 | BR8: 0 | BS8: 0 | BT8: 0 | BU8: 1 | BV8: 3 | BW8: 0 | BX8: 1 | BY8: Bilateral CCA plaques
A9: FY | B9: Kiran shinde | C9: shinde kiran | D9: 0 | E9: 157.513 | F9: 240000065472 | G9: 45 | H9: 1 | I9: 45501 | J9: 0.58333333 | K9: 45501 | L9: 45518 | M9: 8518971856 | O9: 12 | P9: 2 | Q9: 2 | R9: 1 | S9: 1 | T9: 2 | U9: 2 | V9: 2 | W9: 2 | X9: 2 | Y9: 2 | Z9: Hyperhomocystiemia | AA9: 16 | AB9: 48.3 | AC9: 99.6 | AD9: 16.74 | AE9: 4.5 | AF9: 125 | AG9: 66.8 | AH9: 48 | AI9: 51 | AJ9: 10.2 | AK9: 151 | AO9: Rt ACA and Rt MCA superior division infract with hemorrhagic conversion | AQ9: Right ICA occlusion and Rt MCA M1 occlusion | AS9: 8 | AT9: 2 | AU9: 2 | AV9: 2 | AW9: 2 | AY9: 1 | AZ9: 1 | BA9: 1 | BB9: 1 | BD9: 1 | BE9: 1 | BF9: 4 | BG9: 45 | BH9: 0 | BI9: 0 | BJ9: 0 | BK9: 0 | BL9: 1 | BM9: 1 | BN9: 1 | BO9: 0 | BP9: 0 | BQ9: 0 | BR9: 0 | BS9: 0 | BT9: 0 | BU9: 0 | BV9: 3 | BW9: 1 | BX9: 0 | BY9: 0
A10: AO | B10: Mahavar Bappa | C10: Mahavar Bappa | D10: 0 | E10: 74.4875 | F10: 230902350 | G10: 50 | H10: 1 | I10: 45183 | J10: 0.85416667 | K10: 45184 | L10: 45191 | M10: 8855061463 | N10: 8010603917 | O10: 13 | P10: 1 | Q10: 2 | R10: 1 | S10: 1 | T10: 1 | U10: 2 | V10: 2 | W10: 2 | X10: 2 | Y10: 2 | Z10: Dimorphic Anemia | AA10: 11.3 | AB10: 32 | AC10: 79 | AD10: 44.6 | AE10: 5.3 | AF10: 195 | AG10: 116 | AH10: 46 | AI10: 162 | AJ10: 32 | AK10: 148 | AM10: S Iron -19, S TIBC- 317, S UIBC-298, S Feritin- 28, Transferrin saturation-5.99 | AO10: Right MCA Infarct | AQ10: A/c NHI in rt MCA territory. Thyrmbosis in rt MCA distal to origin Eccentric thrymbos in rt carotid bulb. Sanccular aneurysm noted at junction in left ACA and ACOM measuring6x6.7x5.4mm | AS10: 8 | AT10: 2 | AU10: 1 | AV10: 2 | AW10: 4 | AY10: 1 | AZ10: 2 | BA10: 2 | BB10: 2 | BC10: 2 | BD10: 2 | BE10: 2 | BF10: 0 | BG10: 100 | BH10: 1 | BI10: 2 | BJ10: 0 | BK10: 0 | BL10: 0 | BM10: 0 | BN10: 1 | BO10: 0 | BP10: 0 | BQ10: 0 | BR10: 0 | BS10: 0 | BT10: 0 | BU10: 0 | BV10: 4 | BW10: 1 | BX10: 0 | BY10: 0
A11: MD | B11: Ashok Gite | C11: ASHOK GITE | D11: 0 | E11: 13.3671 | F11: 240000048201 | G11: 57 | H11: 1 | I11: 45442 | J11: 0.64583333 | K11: 45443 | L11: 45448 | M11: 997532928 | N11: 9096159020 | O11: 7 | P11: 1 | Q11: 1 | R11: 2 | S11: 1 | T11: 2 | U11: 2 | V11: 2 | W11: 1 | X11: 2 | Y11: 2 | AA11: 14.3 | AB11: 44.4 | AC11: 81.8 | AD11: 20.17 | AE11: 7 | AF11: 141 | AG11: 88.4 | AH11: 29 | AI11: 118 | AJ11: 23.6 | AK11: 208 | AO11: Right corona radiata; medical temporal lobe patchy infract in Rt periatrial region and left caudate region | AQ11: Right M1 stenosis, left V4 stenosis | AS11: 7 | AT11: 2 | AU11: 1 | AV11: 2 | AW11: 5 | AY11: 1 | AZ11: 1 | BA11: 2 | BD11: 2 | BE11: 2 | BF11: 0 | BG11: 100 | BH11: 0 | BI11: 1 | BJ11: 0 | BK11: 1 | BL11: 1 | BM11: 1 | BN11: 1 | BO11: 0 | BP11: 0 | BQ11: 0 | BR11: 0 | BS11: 0 | BT11: 0 | BU11: 0 | BV11: 5 | BW11: 1 | BX11: 0 | BY11: 0
A12: AZ | B12: Jaydep B Panchal | C12: Jaydeep Panchal | D12: 1 | E12: 12.2628 | F12: 231002549 | G12: 30 | H12: 1 | I12: 45220 | J12: 0.54166667 | K12: 45220 | L12: 45220 | M12: 8805207125 | O12: 9 | P12: 2 | Q12: 2 | R12: 1 | S12: 2 | T12: 1 | U12: 2 | V12: 2 | W12: 2 | X12: 2 | Y12: 1 | AO12: acute stroke in Rt thalamus globus pallidus caudate nucleus and anterior limb internal capsule | AQ12: Right m1 occlusion | AS12: 10 | AT12: 2 | AU12: 2 | AV12: 2 | AW12: 4 | AY12: 1 | AZ12: 2 | BA12: 1 | BB12: 1 | BF12: 0 | BG12: 95 | BH12: 1 | BI12: 2 | BJ12: 0 | BK12: 0 | BL12: 1 | BM12: 1 | BN12: 1 | BO12: 0 | BP12: 0 | BQ12: 0 | BR12: 0 | BS12: 0 | BT12: 0 | BU12: 0 | BV12: 6 | BW12: 1 | BX12: 1 | BY12: 0
A13: BA | B13: Malusare suresh | C13: Malsure Suresh, 230000037875 | D13: 1 | E13: 29.0588 | F13: 230904245 | G13: 70 | H13: 1 | I13: 45187 | J13: 0.45833333 | K13: 45198 | L13: 45199 | M13: 9168935500 | P13: 2 | Q13: 1 | R13: 2 | S13: 1 | T13: 2 | U13: 2 | V13: 2 | W13: 2 | X13: 2 | Y13: 2 | AA13: 12 | AB13: 30.2 | AC13: 78.2 | AD13: 37.22 | AE13: 11 | AF13: 137 | AG13: 82.4 | AH13: 40 | AI13: 73 | AJ13: 14.6 | AK13: 7200 | AM13: S. ferritin- 247, S. Iron - 47, S.TIBC- 198, S.UIBC-151, Transferrin Saturation- 23 | AO13: Lt FPT infract and Lt MCA teritory infract | AQ13: Thrombrosis of Lt MCA distal to M1 segment | AS13: 1 | AT13: 2 | AU13: 2 | AV13: 1 | AW13: 2 | AY13: 1 | AZ13: 1 | BA13: 2 | BC13: 4 | BF13: 0 | BG13: 85 | BH13: 0 | BI13: 0 | BJ13: 0 | BK13: 0 | BL13: 0 | BM13: 0 | BN13: 0 | BO13: 1 | BP13: 2 | BQ13: 2 | BR13: 0 | BS13: 0 | BT13: 0 | BU13: 1 | BV13: 6 | BW13: 1 | BX13: 1 | BY13: 0
A14: AV | B14: Nitikesh Gaikwad | C14: #N/A | E14: 95.2161 | F14: 240000082672 | G14: 26 | H14: 1 | I14: 45559 | J14: 0.45833333 | K14: 45559 | L14: 45570 | M14: 8788359008 | O14: 16 | P14: 2 | Q14: 2 | R14: 1 | S14: 2 | T14: 1 | U14: 2 | V14: 2 | W14: 2 | X14: 2 | Y14: 2 | AA14: 15.5 | AB14: 45 | AC14: 11 | AD14: 19.3 | AF14: 95 | AG14: 48 | AH14: 31 | AI14: 76 | AJ14: 15.2 | AK14: 148 | AM14: ANA nuclear , coarse speckled positive ESR 7,CRP 81.4 | AO14: Left M1 MCA infract | AQ14: Left CCA plaque 60-70% stenosis, Left M1 thrombosis | AS14: 9 | AT14: 2 | AU14: 2 | AV14: 2 | AW14: 4 | AY14: 1 | AZ14: 2 | BA14: 1 | BB14: 2 | BC14: 4 | BD14: 2 | BE14: 2 | BO14: 1 | BP14: 2 | BQ14: 0 | BR14: 0 | BS14: 1 | BT14: 1 | BU14: 1 | BV14: 6 | BW14: 0 | BX14: 1 | BY14: 1
A15: LI | B15: Keshavbai shinde | C15: Keshavbai Shinde | D15: 0 | E15: 4.58161 | F15: 24000059976 | G15: 50 | H15: 2 | I15: 45483 | J15: 0.28125 | K15: 45483 | M15: 9096343363 | O15: 3 | P15: 2 | Q15: 2 | R15: 2 | S15: 1 | T15: 2 | U15: 2 | V15: 2 | W15: 2 | X15: 2 | Y15: 2 | AA15: 13.2 | AB15: 40.3 | AC15: 76.5 | AD15: 7.34 | AE15: 5.8 | AF15: 173 | AG15: 102.8 | AH15: 39 | AI15: 156 | AJ15: 31.2 | AK15: 1099 | AO15: Left insular infract | AQ15: Left ICA occluted from origin (100%) and left M3 infract | AS15: 10 | AT15: 2 | AU15: 2 | AV15: 1 | AW15: 4 | AY15: 2 | AZ15: 2 | BA15: 2 | BD15: 2 | BE15: 2 | BF15: 0 | BG15: 100 | BH15: 0 | BI15: 0 | BJ15: 0 | BK15: 0 | BL15: 0 | BM15: 0 | BN15: 0 | BO15: 0 | BP15: 0 | BQ15: 2 | BR15: 2 | BS15: 1 | BT15: 1 | BU15: 1 | BV15: 7 | BW15: 0 | BX15: 1 | BY15: 0
A16: BN | B16: Rekha Bhapkar | C16: Bhapkar rekha | D16: 0 | E16: 18.9935 | F16: 24000021837 | G16: 67 | H16: 2 | I16: 45451 | J16: 0.5 | K16: 45451 | L16: 18-08-2024 | M16: 7767089009 | O16: 23 | P16: 2 | Q16: 2 | R16: 2 | S16: 2 | T16: 2 | U16: 2 | V16: 2 | W16: 2 | X16: 1 | Y16: 2 | AA16: 9.4 | AB16: 29.3 | AC16: 95.9 | AO16: Rt MCA tertiory infract | AQ16: Rt CCA from origin occluded Left ICA occluded from origin | AS16: 8 | AT16: 2 | AU16: 2 | AV16: 3 | AW16: 4 | AY16: 1 | AZ16: 1 | BA16: 2 | BD16: 2 | BE16: 2 | BF16: 6 | BG16: 0 | BH16: 0 | BI16: 0 | BJ16: 2 | BK16: 2 | BL16: 1 | BM16: 1 | BN16: 1 | BO16: 0 | BP16: 0 | BQ16: 0 | BR16: 0 | BS16: 0 | BT16: 0 | BU16: 0 | BV16: 7 | BW16: 1 | BX16: 0 | BY16: Right CCA plaque
A17: BI | B17: Lalbahadur singh | C17: Lalbahadur Singh | D17: 1 | E17: 31.8582 | F17: 240000030601 | G17: 70 | H17: 1 | I17: 45380 | J17: 0.875 | K17: 45381 | M17: 8956146855 | N17: 9699024966 | O17: 14 | P17: 2 | Q17: 2 | R17: 1 | S17: 2 | T17: 1 | U17: 2 | V17: 2 | W17: 2 | X17: 2 | Y17: 2 | AA17: 13.5 | AB17: 41.4 | AC17: 87.6 | AD17: 41.69 | AE17: 6.9 | AF17: 195 | AG17: 125.2 | AH17: 50 | AI17: 99 | AJ17: 19.8 | AK17: 162 | AO17: Right PCA- MCA watershed and Rt MCA teritory watershed infract | AQ17: Right MCA M2 thrombosis; | AS17: 8 | AT17: 2 | AU17: 2 | AV17: 3 | AW17: 4 | AY17: 1 | AZ17: 2 | BA17: 2 | BD17: 2 | BE17: 2 | BF17: 0 | BG17: 80 | BH17: 0 | BI17: 2 | BJ17: 2 | BK17: 0 | BL17: 1 | BM17: 1 | BN17: 1 | BO17: 0 | BP17: 0 | BQ17: 0 | BR17: 0 | BS17: 0 | BT17: 0 | BU17: 0 | BV17: 7 | BW17: 1 | BX17: 1 | BY17: 0
B18: Kiran Pardeshi | C18: #N/A | D18: #N/A | E18: 0.114729 | F18: 240000041820 | G18: 71 | H18: 1 | I18: 45421 | J18: 0.58333333 | K18: 45421 | L18: 45422 | M18: 9011817556 | O18: 3 | P18: 2 | Q18: 2 | R18: 1 | S18: 1 | T18: 2 | U18: 2 | V18: 2 | W18: 2 | X18: 2 | Y18: 2 | AA18: 18 | AB18: 53.8 | AC18: 10.59 | AD18: 29.81 | AK18: 148 | AM18: ESR-13, CRP-42 | AO18: Left insular region tiny infract | AQ18: Left M1 stenosis basilar artery right stenosis | AS18: 8 | AT18: 2 | AU18: 1 | AV18: 2 | AW18: 4 | AY18: 1 | AZ18: 1 | BA18: 2 | BD18: 2 | BE18: 2 | BF18: 0 | BG18: 100 | BO18: 0 | BP18: 1 | BQ18: 2 | BR18: 2 | BS18: 1 | BT18: 1 | BU18: 1 | BV18: 8 | BW18: 1 | BX18: 1 | BY18: Bilateral CCA plaque
A19: JR | B19: Akbar Bhagawan | C19: akbar bhagwan | D19: 0 | E19: 8.88232 | F19: 240000076798 | G19: 43 | H19: 1 | I19: 45537 | J19: 0.34375 | K19: 45537 | L19: 45551 | M19: 9960441201 | O19: 12 | P19: 1 | Q19: 1 | R19: 2 | S19: 2 | T19: 2 | U19: 2 | V19: 2 | W19: 1 | X19: 2 | Y19: 2 | Z19: PTCA to LCX done on 29/08/2024,heart failuar EF 40%, poliomyelitis | AA19: 10.5 | AB19: 32.7 | AC19: 79.4 | AD19: 10.77 | AF19: 190 | AG19: 135 | AH19: 25 | AI19: 150 | AJ19: 30 | AK19: 259 | AO19: Left MCA patchy infract | AQ19: Left ICA occlusion from origin, reformation of cavernous ICA from MMA | AS19: 9 | AT19: 2 | AU19: 1 | AV19: 3 | AW19: 4 | AY19: 1 | AZ19: 1 | BA19: 2 | BC19: 4 | BD19: 2 | BE19: 2 | BF19: 6 | BG19: 0 | BO19: 0 | BP19: 1 | BQ19: 2 | BR19: 2 | BS19: 1 | BT19: 1 | BU19: 1 | BV19: 8 | BW19: 0 | BX19: 1 | BY19: 0
A20: CR | B20: Indubai Sarang | C20: sarang indubai | D20: 0 | E20: 25.4023 | F20: 240000064726 | G20: 80 | H20: 2 | I20: 45496 | K20: 45498 | M20: 9970695458 | O20: 17 | P20: 1 | Q20: 1 | R20: 2 | S20: 2 | T20: 2 | U20: 2 | V20: 2 | W20: 2 | X20: 2 | Y20: 2 | AA20: 12.9 | AB20: 38.5 | AC20: 92 | AD20: 31.04 | AE20: 11.4 | AF20: 130 | AG20: 68.8 | AH20: 31 | AI20: 151 | AJ20: 30.2 | AK20: 198 | AO20: Acute infract seen in cortical and subcortical white matter of Lt frontal, parietal and temporal lobe, Lt centrum semiovale, Lt corona radiata and Lt lentiform nucleus | AQ20: Atherosclerotic plaque at Lt carotid bulb narrowing Rt ICA . the plaque extends =10 mm ICA distal narrowing upto 6.4mm causing 50-60% | AS20: 9 | AT20: 2 | AU20: 2 | AV20: 3 | AW20: 4 | AY20: 1 | AZ20: 1 | BA20: 2 | BD20: 2 | BE20: 2 | BF20: 5 | BG20: 100 | BH20: 0 | BI20: 0 | BJ20: 0 | BK20: 0 | BL20: 0 | BM20: 0 | BN20: 0 | BO20: 0 | BP20: 2 | BQ20: 1 | BR20: 2 | BS20: 1 | BT20: 1 | BU20: 1 | BV20: 8 | BW20: 1 | BX20: 0 | BY20: 0
B21: Varsha Patil/ Pawar | C21: #N/A | D21: #N/A | E21: 35.3162 | F21: 240000053520 | G21: 38 | H21: 2 | I21: 45462 | J21: 0.30208333 | K21: 45462 | L21: 45468 | M21: 7666761395 | O21: 17 | P21: 2 | Q21: 2 | R21: 2 | S21: 2 | T21: 2 | U21: 2 | V21: 2 | W21: 2 | X21: 2 | Y21: 2 | AA21: 12 | AB21: 35.4 | AC21: 90 | AD21: 12.75 | AE21: 5.5 | AK21: 166 | AM21: AMA, APLA, ESR-2, CRP-16 | AO21: Acute NHI in left P-T region and left insular cortex occlusion of superior division of left MCA with reconalization of inferior division | AQ21: Left M1 occlusion (superior division) | AS21: 9 | AT21: 2 | AU21: 2 | AV21: 2 | AW21: 4 | AY21: 1 | BA21: 1 | BB21: 2 | BD21: 2 | BE21: 2 | BF21: 1 | BG21: 100 | BO21: 1 | BP21: 2 | BQ21: 0 | BR21: 2 | BS21: 1 | BT21: 1 | BU21: 1 | BV21: 8 | BW21: 1 | BX21: 1 | BY21: 1
A22: CK | B22: Chandrakant Khopade | C22: Chandrakant Khopade | D22: 0 | E22: 129.428 | F22: 190402865 | G22: 60 | H22: 1 | I22: 44941 | J22: 0.3125 | K22: 44941 | L22: 44960 | M22: 9067030236 | O22: 18 | P22: 2 | Q22: 2 | R22: 2 | S22: 2 | T22: 2 | U22: 2 | V22: 1 | W22: 2 | X22: 2 | Y22: 2 | AA22: 14 | AB22: 32 | AC22: 95 | AD22: 22 | AE22: 5.5 | AK22: 171 | AO22: Right MCA infract | AQ22: Non opacification of left ICA from its origin s/o occlusional thrombosis. non-opacification of M1, M2 and proximal M2 segments of right MCA | AS22: 3 | AT22: 2 | AU22: 2 | AV22: 1 | AW22: 3 | AY22: 1 | AZ22: 2 | BA22: 1 | BB22: 1 | BC22: 3 | BF22: 4 | BG22: 30 | BH22: 1 | BI22: 2 | BJ22: 2 | BK22: 0 | BL22: 1 | BM22: 1 | BN22: 1 | BO22: 0 | BP22: 0 | BQ22: 0 | BR22: 0 | BS22: 0 | BT22: 0 | BU22: 0 | BV22: 8 | BW22: 1 | BX22: 1 | BY22: 0
A23: FK | B23: Lahot Krushna | C23: #N/A | D23: #N/A | E23: #N/A | F23: 240000078257 | G23: 74 | H23: 2 | I23: 45544 | J23: 0.10416667 | K23: 45544 | L23: 45560 | M23: 7448240702 | O23: 11 | P23: 1 | Q23: 1 | R23: 2 | S23: 2 | T23: 2 | U23: 2 | V23: 2 | W23: 1 | X23: 2 | Y23: 2 | AA23: 11.8 | AB23: 36.7 | AC23: 90.4 | AD23: 13.29 | AE23: 6.7 | AF23: 153 | AG23: 96 | AH23: 34 | AI23: 111 | AJ23: 22 | AK23: 397 | AO23: Rt MCA infarct superior division | AQ23: Rt MCA supeiror devision thrombus, atherosclerotic plaque with calcifications in left carotid bulb and origin of left ICA | AS23: 4 | AT23: 2 | AU23: 2 | AV23: 3 | AW23: 3 | AY23: 1 | AZ23: 1 | BA23: 1 | BB23: 1 | BC23: 4 | BD23: 2 | BE23: 2 | BF23: 6 | BG23: 0 | BH23: 0 | BI23: 1 | BJ23: 2 | BK23: 2 | BL23: 1 | BM23: 1 | BN23: 1 | BV23: 8 | BW23: 0 | BX23: 1
A24: FQ | B24: Dharmendra Kale | C24: Kale Dharmendra | D24: 1 | E24: 0.363236 | F24: 120502937 | G24: 47 | H24: 1 | K24: 44970 | L24: 44972 | O24: 0 | P24: 1 | Q24: 2 | R24: 2 | S24: 2 | T24: 2 | U24: 2 | V24: 2 | W24: 2 | X24: 2 | Y24: 2 | AA24: 12.9 | AB24: 39 | AC24: 80 | AD24: 40 | AE24: 5.8 | AK24: 177 | AO24: ASL hypoperfusion segmet left fronto parietal region | AQ24: Short segment narrowing supraclinoid segment of left ICA | AS24: 10 | AT24: 2 | AU24: 1 | AV24: 3 | AW24: 4 | AY24: 1 | AZ24: 1 | BA24: 2 | BD24: 2 | BE24: 2 | BF24: 0 | BG24: 100 | BH24: 0 | BI24: 0 | BJ24: 0 | BK24: 0 | BL24: 0 | BM24: 0 | BN24: 0 | BO24: 1 | BP24: 1 | BQ24: 2 | BR24: 2 | BS24: 1 | BT24: 1 | BU24: 1 | BV24: 9 | BW24: 1 | BX24: 1 | BY24: Left CCA plaque
A25: FG | B25: Vilas Gaikwad | C25: VILAS GAIKWAD | D25: 0 | E25: 0.682883 | F25: 240020598 | G25: 51 | H25: 1 | I25: 45430 | J25: 0.37083333 | K25: 45430 | L25: 45447 | M25: 8149081492 | O25: 20 | P25: 1 | Q25: 1 | R25: 1 | S25: 1 | T25: 1 | U25: 2 | V25: 2 | W25: 2 | X25: 2 | Y25: 2 | AA25: 8.5 | AB25: 29.3 | AC25: 59.7 | AD25: 4.36 | AE25: 8.2 | AF25: 90 | AG25: 42.2 | AH25: 21 | AI25: 134 | AJ25: 26.3 | AK25: 795 | AM25: CRP- 180, ESR-16, ferritin-383, S IRon-82, UIBC-200,TIBC- 282, transferrin saturation-29.7 | AO25: Acute NHI in Lt MCA teritory | AQ25: Normal with filling detect in the left carotid bifurcation | AS25: 3 | AT25: 2 | AU25: 2 | AV25: 2 | AW25: 3 | AY25: 1 | BA25: 2 | BB25: 1 | BD25: 2 | BE25: 2 | BF25: 3 | BG25: 55 | BH25: 0 | BI25: 0 | BJ25: 0 | BK25: 0 | BL25: 0 | BM25: 0 | BN25: 0 | BO25: 1 | BP25: 2 | BQ25: 2 | BR25: 2 | BS25: 0 | BT25: 1 | BU25: 1 | BV25: 9 | BW25: 0 | BX25: 1 | BY25: 0
